2020-05-15 14:09:29,540 - xici_ip_model.py[line:41] - ERROR: HTTPSConnectionPool(host='www.xicidaili.com', port=443): Max retries exceeded with url: /nn/2.html (Caused by ProxyError('Cannot connect to proxy.', NewConnectionError('<urllib3.connection.VerifiedHTTPSConnection object at 0x00000261BA1CD308>: Failed to establish a new connection: [WinError 10061] 由于目标计算机积极拒绝，无法连接。')))
2020-05-15 14:09:30,843 - xici_ip_model.py[line:41] - ERROR: HTTPSConnectionPool(host='www.xicidaili.com', port=443): Max retries exceeded with url: /nn/3.html (Caused by ProxyError('Cannot connect to proxy.', ConnectionAbortedError(10053, '你的主机中的软件中止了一个已建立的连接。', None, 10053, None)))
2020-05-15 14:09:31,576 - xici_ip_model.py[line:41] - ERROR: HTTPSConnectionPool(host='www.xicidaili.com', port=443): Max retries exceeded with url: /nn/4.html (Caused by ProxyError('Cannot connect to proxy.', ConnectionAbortedError(10053, '你的主机中的软件中止了一个已建立的连接。', None, 10053, None)))
2020-05-15 14:09:31,736 - xici_ip_model.py[line:41] - ERROR: HTTPSConnectionPool(host='www.xicidaili.com', port=443): Max retries exceeded with url: /nn/5.html (Caused by ProxyError('Cannot connect to proxy.', RemoteDisconnected('Remote end closed connection without response')))
2020-05-15 14:09:32,466 - xici_ip_model.py[line:41] - ERROR: HTTPSConnectionPool(host='www.xicidaili.com', port=443): Max retries exceeded with url: /nn/6.html (Caused by ProxyError('Cannot connect to proxy.', ConnectionAbortedError(10053, '你的主机中的软件中止了一个已建立的连接。', None, 10053, None)))
2020-05-15 14:09:33,698 - xici_ip_model.py[line:41] - ERROR: HTTPSConnectionPool(host='www.xicidaili.com', port=443): Max retries exceeded with url: /nn/7.html (Caused by ProxyError('Cannot connect to proxy.', NewConnectionError('<urllib3.connection.VerifiedHTTPSConnection object at 0x00000261BA0F1E48>: Failed to establish a new connection: [WinError 10061] 由于目标计算机积极拒绝，无法连接。')))
2020-05-15 14:09:34,938 - xici_ip_model.py[line:41] - ERROR: HTTPSConnectionPool(host='www.xicidaili.com', port=443): Max retries exceeded with url: /nn/8.html (Caused by ProxyError('Cannot connect to proxy.', NewConnectionError('<urllib3.connection.VerifiedHTTPSConnection object at 0x00000261BA1D0808>: Failed to establish a new connection: [WinError 10061] 由于目标计算机积极拒绝，无法连接。')))
2020-05-15 14:09:36,178 - xici_ip_model.py[line:41] - ERROR: HTTPSConnectionPool(host='www.xicidaili.com', port=443): Max retries exceeded with url: /nn/9.html (Caused by ProxyError('Cannot connect to proxy.', NewConnectionError('<urllib3.connection.VerifiedHTTPSConnection object at 0x00000261BA1CDBC8>: Failed to establish a new connection: [WinError 10061] 由于目标计算机积极拒绝，无法连接。')))
2020-05-15 14:09:37,408 - xici_ip_model.py[line:41] - ERROR: HTTPSConnectionPool(host='www.xicidaili.com', port=443): Max retries exceeded with url: /nn/10.html (Caused by ProxyError('Cannot connect to proxy.', NewConnectionError('<urllib3.connection.VerifiedHTTPSConnection object at 0x00000261BA1DF688>: Failed to establish a new connection: [WinError 10061] 由于目标计算机积极拒绝，无法连接。')))
2020-05-15 14:09:38,637 - xici_ip_model.py[line:41] - ERROR: HTTPSConnectionPool(host='www.xicidaili.com', port=443): Max retries exceeded with url: /nn/11.html (Caused by ProxyError('Cannot connect to proxy.', NewConnectionError('<urllib3.connection.VerifiedHTTPSConnection object at 0x00000261BA1D5688>: Failed to establish a new connection: [WinError 10061] 由于目标计算机积极拒绝，无法连接。')))
2020-05-15 14:09:39,872 - xici_ip_model.py[line:41] - ERROR: HTTPSConnectionPool(host='www.xicidaili.com', port=443): Max retries exceeded with url: /nn/12.html (Caused by ProxyError('Cannot connect to proxy.', NewConnectionError('<urllib3.connection.VerifiedHTTPSConnection object at 0x00000261BA1ED6C8>: Failed to establish a new connection: [WinError 10061] 由于目标计算机积极拒绝，无法连接。')))
2020-05-15 14:09:41,112 - xici_ip_model.py[line:41] - ERROR: HTTPSConnectionPool(host='www.xicidaili.com', port=443): Max retries exceeded with url: /nn/13.html (Caused by ProxyError('Cannot connect to proxy.', NewConnectionError('<urllib3.connection.VerifiedHTTPSConnection object at 0x00000261BA1D5F88>: Failed to establish a new connection: [WinError 10061] 由于目标计算机积极拒绝，无法连接。')))
2020-05-15 14:09:42,343 - xici_ip_model.py[line:41] - ERROR: HTTPSConnectionPool(host='www.xicidaili.com', port=443): Max retries exceeded with url: /nn/14.html (Caused by ProxyError('Cannot connect to proxy.', NewConnectionError('<urllib3.connection.VerifiedHTTPSConnection object at 0x00000261BA1ED388>: Failed to establish a new connection: [WinError 10061] 由于目标计算机积极拒绝，无法连接。')))
2020-05-15 14:09:43,575 - xici_ip_model.py[line:41] - ERROR: HTTPSConnectionPool(host='www.xicidaili.com', port=443): Max retries exceeded with url: /nn/15.html (Caused by ProxyError('Cannot connect to proxy.', NewConnectionError('<urllib3.connection.VerifiedHTTPSConnection object at 0x00000261BA1DF648>: Failed to establish a new connection: [WinError 10061] 由于目标计算机积极拒绝，无法连接。')))
2020-05-15 14:12:08,023 - redis_memory.py[line:64] - INFO: ('set row', '114.104.142.233:8691')
2020-05-15 14:12:08,025 - redis_memory.py[line:64] - INFO: ('set row', '114.104.142.115:9999')
2020-05-15 14:12:08,026 - redis_memory.py[line:64] - INFO: ('set row', '122.246.94.2:8118')
2020-05-15 14:12:08,028 - redis_memory.py[line:64] - INFO: ('set row', '124.112.105.244:4216')
2020-05-15 14:12:08,030 - redis_memory.py[line:64] - INFO: ('set row', '223.68.190.130:8181')
2020-05-15 14:12:08,032 - redis_memory.py[line:64] - INFO: ('set row', '42.59.87.91:1133')
2020-05-15 14:12:08,034 - redis_memory.py[line:64] - INFO: ('set row', '60.188.13.167:3000')
2020-05-15 14:12:08,036 - redis_memory.py[line:64] - INFO: ('set row', '58.254.220.116:52470')
2020-05-15 14:12:08,038 - redis_memory.py[line:64] - INFO: ('set row', '59.44.78.30:42335')
2020-05-15 14:12:08,040 - redis_memory.py[line:64] - INFO: ('set row', '115.208.67.226:8118')
2020-05-15 14:12:08,041 - redis_memory.py[line:64] - INFO: ('set row', '223.215.107.118:4216')
2020-05-15 14:12:08,044 - redis_memory.py[line:64] - INFO: ('set row', '223.215.106.254:4216')
2020-05-15 14:12:08,046 - redis_memory.py[line:64] - INFO: ('set row', '223.215.100.90:4216')
2020-05-15 14:12:08,048 - redis_memory.py[line:64] - INFO: ('set row', '223.215.103.243:4216')
2020-05-15 14:12:08,050 - redis_memory.py[line:64] - INFO: ('set row', '223.215.107.36:4216')
2020-05-15 14:12:08,052 - redis_memory.py[line:64] - INFO: ('set row', '223.215.103.118:4216')
2020-05-15 14:12:08,054 - redis_memory.py[line:64] - INFO: ('set row', '122.241.201.140:3000')
2020-05-15 14:12:08,056 - redis_memory.py[line:64] - INFO: ('set row', '183.166.252.62:4216')
2020-05-15 14:12:08,058 - redis_memory.py[line:64] - INFO: ('set row', '183.166.250.187:4216')
2020-05-15 14:12:08,060 - redis_memory.py[line:64] - INFO: ('set row', '117.88.177.87:3000')
2020-05-15 14:12:08,062 - redis_memory.py[line:64] - INFO: ('set row', '222.95.144.55:3000')
2020-05-15 14:12:08,064 - redis_memory.py[line:64] - INFO: ('set row', '124.112.104.62:4216')
2020-05-15 14:12:08,066 - redis_memory.py[line:64] - INFO: ('set row', '117.88.176.114:3000')
2020-05-15 14:12:08,069 - redis_memory.py[line:64] - INFO: ('set row', '117.88.176.84:3000')
2020-05-15 14:12:08,071 - redis_memory.py[line:64] - INFO: ('set row', '121.237.149.70:3000')
2020-05-15 14:12:08,073 - redis_memory.py[line:64] - INFO: ('set row', '111.72.25.79:10086')
2020-05-15 14:12:08,076 - redis_memory.py[line:64] - INFO: ('set row', '117.88.4.205:3000')
2020-05-15 14:12:08,078 - redis_memory.py[line:64] - INFO: ('set row', '114.104.139.164:8691')
2020-05-15 14:12:08,080 - redis_memory.py[line:64] - INFO: ('set row', '114.104.139.245:8691')
2020-05-15 14:12:08,082 - redis_memory.py[line:64] - INFO: ('set row', '223.215.102.109:4216')
2020-05-15 14:12:08,085 - redis_memory.py[line:64] - INFO: ('set row', '117.69.152.146:8691')
2020-05-15 14:12:08,087 - redis_memory.py[line:64] - INFO: ('set row', '117.69.153.137:8691')
2020-05-15 14:12:08,090 - redis_memory.py[line:64] - INFO: ('set row', '117.88.177.231:3000')
2020-05-15 14:12:08,093 - redis_memory.py[line:64] - INFO: ('set row', '49.85.99.29:10098')
2020-05-15 14:12:08,095 - redis_memory.py[line:64] - INFO: ('set row', '139.196.34.166:80')
2020-05-15 14:12:08,099 - redis_memory.py[line:64] - INFO: ('set row', '111.222.120.140:8118')
2020-05-15 14:12:08,100 - redis_memory.py[line:64] - INFO: ('set row', '111.229.103.188:8080')
2020-05-15 14:12:08,103 - redis_memory.py[line:64] - INFO: ('set row', '117.88.176.237:3000')
2020-05-15 14:12:08,106 - redis_memory.py[line:64] - INFO: ('set row', '183.166.251.22:4216')
2020-05-15 14:12:08,109 - redis_memory.py[line:64] - INFO: ('set row', '124.112.105.141:4216')
2020-05-15 14:12:08,112 - redis_memory.py[line:64] - INFO: ('set row', '124.112.104.84:4216')
2020-05-15 14:12:08,115 - redis_memory.py[line:64] - INFO: ('set row', '27.188.62.3:8060')
2020-05-15 14:12:08,117 - redis_memory.py[line:64] - INFO: ('set row', '121.17.210.114:8060')
2020-05-15 14:12:08,119 - redis_memory.py[line:64] - INFO: ('set row', '223.215.101.143:4216')
2020-05-15 14:12:08,122 - redis_memory.py[line:64] - INFO: ('set row', '60.188.11.110:3000')
2020-05-15 14:12:08,126 - redis_memory.py[line:64] - INFO: ('set row', '114.104.139.93:8691')
2020-05-15 14:12:08,128 - redis_memory.py[line:64] - INFO: ('set row', '117.69.152.162:8691')
2020-05-15 14:12:08,132 - redis_memory.py[line:64] - INFO: ('set row', '223.215.103.53:4216')
2020-05-15 14:12:08,135 - redis_memory.py[line:64] - INFO: ('set row', '115.199.131.42:8060')
2020-05-15 14:12:08,138 - redis_memory.py[line:64] - INFO: ('set row', '183.166.249.36:4216')
2020-05-15 14:12:08,141 - redis_memory.py[line:64] - INFO: ('set row', '183.166.138.7:16066')
2020-05-15 14:12:08,144 - redis_memory.py[line:64] - INFO: ('set row', '49.81.26.213:4216')
2020-05-15 14:12:08,147 - redis_memory.py[line:64] - INFO: ('set row', '125.123.153.85:3000')
2020-05-15 14:12:08,150 - redis_memory.py[line:64] - INFO: ('set row', '119.254.94.71:42788')
2020-05-15 14:12:08,154 - redis_memory.py[line:64] - INFO: ('set row', '117.69.181.247:4216')
2020-05-15 14:12:08,157 - redis_memory.py[line:64] - INFO: ('set row', '106.122.205.90:8118')
2020-05-15 14:12:08,160 - redis_memory.py[line:64] - INFO: ('set row', '114.216.50.188:8118')
2020-05-15 14:12:08,163 - redis_memory.py[line:64] - INFO: ('set row', '124.112.105.1:4216')
2020-05-15 14:12:08,167 - redis_memory.py[line:64] - INFO: ('set row', '183.166.249.20:4216')
2020-05-15 14:12:08,170 - redis_memory.py[line:64] - INFO: ('set row', '49.85.162.175:10098')
2020-05-15 14:12:08,173 - redis_memory.py[line:64] - INFO: ('set row', '180.122.224.55:8888')
2020-05-15 14:12:08,176 - redis_memory.py[line:64] - INFO: ('set row', '117.45.139.230:9006')
2020-05-15 14:12:08,179 - redis_memory.py[line:64] - INFO: ('set row', '221.236.112.112:8118')
2020-05-15 14:12:08,182 - redis_memory.py[line:64] - INFO: ('set row', '139.224.16.103:8080')
2020-05-15 14:12:08,185 - redis_memory.py[line:64] - INFO: ('set row', '121.237.149.242:3000')
2020-05-15 14:12:08,189 - redis_memory.py[line:64] - INFO: ('set row', '122.235.188.241:8118')
2020-05-15 14:12:08,192 - redis_memory.py[line:64] - INFO: ('set row', '117.69.151.6:4216')
2020-05-15 14:12:08,195 - redis_memory.py[line:64] - INFO: ('set row', '117.69.130.123:8691')
2020-05-15 14:12:08,198 - redis_memory.py[line:64] - INFO: ('set row', '117.88.4.191:3000')
2020-05-15 14:12:08,202 - redis_memory.py[line:64] - INFO: ('set row', '117.69.130.103:8691')
2020-05-15 14:12:08,205 - redis_memory.py[line:64] - INFO: ('set row', '183.146.114.184:8118')
2020-05-15 14:12:08,208 - redis_memory.py[line:64] - INFO: ('set row', '117.88.177.197:3000')
2020-05-15 14:12:08,211 - redis_memory.py[line:64] - INFO: ('set row', '218.67.94.133:3128')
2020-05-15 14:12:08,214 - redis_memory.py[line:64] - INFO: ('set row', '117.69.153.238:4216')
2020-05-15 14:12:08,217 - redis_memory.py[line:64] - INFO: ('set row', '183.166.253.96:4216')
2020-05-15 14:12:08,220 - redis_memory.py[line:64] - INFO: ('set row', '221.193.168.32:8118')
2020-05-15 14:12:08,224 - redis_memory.py[line:64] - INFO: ('set row', '114.221.143.172:8118')
2020-05-15 14:12:08,227 - redis_memory.py[line:64] - INFO: ('set row', '125.121.92.64:8118')
2020-05-15 14:12:08,230 - redis_memory.py[line:64] - INFO: ('set row', '183.166.249.3:4216')
2020-05-15 14:12:08,234 - redis_memory.py[line:64] - INFO: ('set row', '125.123.155.237:3000')
2020-05-15 14:12:08,237 - redis_memory.py[line:64] - INFO: ('set row', '114.104.185.244:4216')
2020-05-15 14:12:08,240 - redis_memory.py[line:64] - INFO: ('set row', '125.123.157.194:3000')
2020-05-15 14:12:08,243 - redis_memory.py[line:64] - INFO: ('set row', '49.85.2.14:29639')
2020-05-15 14:12:08,246 - redis_memory.py[line:64] - INFO: ('set row', '49.85.84.225:10098')
2020-05-15 14:12:08,250 - redis_memory.py[line:64] - INFO: ('set row', '49.85.0.185:47253')
2020-05-15 14:12:08,253 - redis_memory.py[line:64] - INFO: ('set row', '125.123.154.160:3000')
2020-05-15 14:12:08,256 - redis_memory.py[line:64] - INFO: ('set row', '114.228.205.11:8118')
2020-05-15 14:12:08,260 - redis_memory.py[line:64] - INFO: ('set row', '114.104.142.191:8691')
2020-05-15 14:12:08,263 - redis_memory.py[line:64] - INFO: ('set row', '123.168.67.96:8118')
2020-05-15 14:12:08,267 - redis_memory.py[line:64] - INFO: ('set row', '125.123.156.148:3000')
2020-05-15 14:12:08,271 - redis_memory.py[line:64] - INFO: ('set row', '125.123.152.159:3000')
2020-05-15 14:12:08,274 - redis_memory.py[line:64] - INFO: ('set row', '183.166.139.23:9999')
2020-05-15 14:12:08,278 - redis_memory.py[line:64] - INFO: ('set row', '115.206.100.87:8060')
2020-05-15 14:12:08,282 - redis_memory.py[line:64] - INFO: ('set row', '117.88.177.127:3000')
2020-05-15 14:12:08,286 - redis_memory.py[line:64] - INFO: ('set row', '211.142.169.4:808')
2020-05-15 14:12:08,290 - redis_memory.py[line:64] - INFO: ('set row', '117.88.177.185:3000')
2020-05-15 14:12:08,294 - redis_memory.py[line:64] - INFO: ('set row', '112.194.112.175:8118')
2020-05-15 14:12:08,297 - redis_memory.py[line:64] - INFO: ('set row', '117.69.152.116:4216')
2020-05-15 14:12:08,301 - redis_memory.py[line:64] - INFO: ('set row', '117.69.171.237:4216')
2020-05-15 14:12:08,305 - redis_memory.py[line:68] - INFO: ('flush', 'xici:xici_proxy_queue', 'exp', 600, 'remove count', 1)
2020-05-15 14:12:12,308 - redis_memory.py[line:64] - INFO: ('set row', '14.114.39.78:8118')
2020-05-15 14:12:13,367 - redis_memory.py[line:68] - INFO: ('flush', 'xici:xici_proxy_queue', 'exp', 600, 'remove count', 0)
2020-05-15 14:12:17,372 - redis_memory.py[line:68] - INFO: ('flush', 'xici:xici_proxy_queue', 'exp', 600, 'remove count', 0)
2020-05-15 14:12:21,383 - redis_memory.py[line:68] - INFO: ('flush', 'xici:xici_proxy_queue', 'exp', 600, 'remove count', 0)
2020-05-15 14:14:31,195 - xici_ip_model.py[line:45] - ERROR: HTTPSConnectionPool(host='www.xicidaili.com', port=443): Max retries exceeded with url: /nn/5.html (Caused by ConnectTimeoutError(<urllib3.connection.VerifiedHTTPSConnection object at 0x000001832030F648>, 'Connection to 1.85.5.66 timed out. (connect timeout=5)'))
2020-05-15 14:14:46,315 - xici_ip_model.py[line:45] - ERROR: HTTPSConnectionPool(host='www.xicidaili.com', port=443): Max retries exceeded with url: /nn/8.html (Caused by ConnectTimeoutError(<urllib3.connection.VerifiedHTTPSConnection object at 0x000001832030FC08>, 'Connection to 101.132.190.101 timed out. (connect timeout=5)'))
2020-05-15 14:15:36,167 - xici_ip_model.py[line:45] - ERROR: HTTPSConnectionPool(host='www.xicidaili.com', port=443): Max retries exceeded with url: /nn/25.html (Caused by ConnectTimeoutError(<urllib3.connection.VerifiedHTTPSConnection object at 0x00000183203E0788>, 'Connection to 58.58.213.55 timed out. (connect timeout=5)'))
2020-05-15 14:17:15,019 - xici_ip_model.py[line:31] - INFO: ('start get 1 page', 'https://www.xicidaili.com/nn/1.html')
2020-05-15 14:17:15,322 - xici_ip_model.py[line:31] - INFO: ('start get 1 page', 'https://www.xicidaili.com/nn/2.html')
2020-05-15 14:17:20,325 - xici_ip_model.py[line:46] - ERROR: HTTPSConnectionPool(host='www.xicidaili.com', port=443): Max retries exceeded with url: /nn/2.html (Caused by ConnectTimeoutError(<urllib3.connection.VerifiedHTTPSConnection object at 0x0000024E6C79D148>, 'Connection to 114.99.54.65 timed out. (connect timeout=5)'))
2020-05-15 14:17:20,328 - xici_ip_model.py[line:31] - INFO: ('start get 1 page', 'https://www.xicidaili.com/nn/3.html')
2020-05-15 14:17:25,331 - xici_ip_model.py[line:46] - ERROR: HTTPSConnectionPool(host='www.xicidaili.com', port=443): Max retries exceeded with url: /nn/3.html (Caused by ConnectTimeoutError(<urllib3.connection.VerifiedHTTPSConnection object at 0x0000024E6C6C0908>, 'Connection to 114.99.54.65 timed out. (connect timeout=5)'))
2020-05-15 14:17:25,332 - xici_ip_model.py[line:31] - INFO: ('start get 1 page', 'https://www.xicidaili.com/nn/4.html')
2020-05-15 14:17:30,333 - xici_ip_model.py[line:46] - ERROR: HTTPSConnectionPool(host='www.xicidaili.com', port=443): Max retries exceeded with url: /nn/4.html (Caused by ConnectTimeoutError(<urllib3.connection.VerifiedHTTPSConnection object at 0x0000024E6C79DAC8>, 'Connection to 114.99.54.65 timed out. (connect timeout=5)'))
2020-05-15 14:17:30,336 - xici_ip_model.py[line:31] - INFO: ('start get 1 page', 'https://www.xicidaili.com/nn/5.html')
2020-05-15 14:17:35,340 - xici_ip_model.py[line:46] - ERROR: HTTPSConnectionPool(host='www.xicidaili.com', port=443): Max retries exceeded with url: /nn/5.html (Caused by ConnectTimeoutError(<urllib3.connection.VerifiedHTTPSConnection object at 0x0000024E6C7A65C8>, 'Connection to 114.99.54.65 timed out. (connect timeout=5)'))
2020-05-15 14:17:35,341 - xici_ip_model.py[line:31] - INFO: ('start get 1 page', 'https://www.xicidaili.com/nn/6.html')
2020-05-15 14:17:40,343 - xici_ip_model.py[line:46] - ERROR: HTTPSConnectionPool(host='www.xicidaili.com', port=443): Max retries exceeded with url: /nn/6.html (Caused by ConnectTimeoutError(<urllib3.connection.VerifiedHTTPSConnection object at 0x0000024E6C7A8648>, 'Connection to 114.99.54.65 timed out. (connect timeout=5)'))
2020-05-15 14:17:40,344 - xici_ip_model.py[line:31] - INFO: ('start get 1 page', 'https://www.xicidaili.com/nn/7.html')
2020-05-15 14:17:45,346 - xici_ip_model.py[line:46] - ERROR: HTTPSConnectionPool(host='www.xicidaili.com', port=443): Max retries exceeded with url: /nn/7.html (Caused by ConnectTimeoutError(<urllib3.connection.VerifiedHTTPSConnection object at 0x0000024E6C7B3788>, 'Connection to 114.99.54.65 timed out. (connect timeout=5)'))
2020-05-15 14:17:45,346 - xici_ip_model.py[line:31] - INFO: ('start get 1 page', 'https://www.xicidaili.com/nn/8.html')
2020-05-15 14:17:45,435 - xici_ip_model.py[line:31] - INFO: ('start get 1 page', 'https://www.xicidaili.com/nn/9.html')
2020-05-15 14:17:50,412 - xici_ip_model.py[line:31] - INFO: ('start get 1 page', 'https://www.xicidaili.com/nn/1.html')
2020-05-15 14:17:50,688 - xici_ip_model.py[line:31] - INFO: ('start get 1 page', 'https://www.xicidaili.com/nn/2.html')
2020-05-15 14:17:55,691 - xici_ip_model.py[line:47] - ERROR: HTTPSConnectionPool(host='www.xicidaili.com', port=443): Max retries exceeded with url: /nn/2.html (Caused by ConnectTimeoutError(<urllib3.connection.VerifiedHTTPSConnection object at 0x0000027B975AD3C8>, 'Connection to 61.160.245.88 timed out. (connect timeout=5)'))
2020-05-15 14:17:55,692 - xici_ip_model.py[line:31] - INFO: ('start get 1 page', 'https://www.xicidaili.com/nn/3.html')
2020-05-15 14:18:00,693 - xici_ip_model.py[line:47] - ERROR: HTTPSConnectionPool(host='www.xicidaili.com', port=443): Max retries exceeded with url: /nn/3.html (Caused by ConnectTimeoutError(<urllib3.connection.VerifiedHTTPSConnection object at 0x0000027B974BF748>, 'Connection to 61.160.245.88 timed out. (connect timeout=5)'))
2020-05-15 14:18:00,694 - xici_ip_model.py[line:31] - INFO: ('start get 1 page', 'https://www.xicidaili.com/nn/4.html')
2020-05-15 14:18:05,695 - xici_ip_model.py[line:47] - ERROR: HTTPSConnectionPool(host='www.xicidaili.com', port=443): Max retries exceeded with url: /nn/4.html (Caused by ConnectTimeoutError(<urllib3.connection.VerifiedHTTPSConnection object at 0x0000027B975B56C8>, 'Connection to 61.160.245.88 timed out. (connect timeout=5)'))
2020-05-15 14:18:05,696 - xici_ip_model.py[line:31] - INFO: ('start get 1 page', 'https://www.xicidaili.com/nn/5.html')
2020-05-15 14:18:10,698 - xici_ip_model.py[line:47] - ERROR: HTTPSConnectionPool(host='www.xicidaili.com', port=443): Max retries exceeded with url: /nn/5.html (Caused by ConnectTimeoutError(<urllib3.connection.VerifiedHTTPSConnection object at 0x0000027B974B31C8>, 'Connection to 61.160.245.88 timed out. (connect timeout=5)'))
2020-05-15 14:18:10,699 - xici_ip_model.py[line:31] - INFO: ('start get 1 page', 'https://www.xicidaili.com/nn/6.html')
2020-05-15 14:18:15,701 - xici_ip_model.py[line:47] - ERROR: HTTPSConnectionPool(host='www.xicidaili.com', port=443): Max retries exceeded with url: /nn/6.html (Caused by ConnectTimeoutError(<urllib3.connection.VerifiedHTTPSConnection object at 0x0000027B975B9688>, 'Connection to 61.160.245.88 timed out. (connect timeout=5)'))
2020-05-15 14:18:15,701 - xici_ip_model.py[line:31] - INFO: ('start get 1 page', 'https://www.xicidaili.com/nn/7.html')
2020-05-15 14:18:20,703 - xici_ip_model.py[line:47] - ERROR: HTTPSConnectionPool(host='www.xicidaili.com', port=443): Max retries exceeded with url: /nn/7.html (Caused by ConnectTimeoutError(<urllib3.connection.VerifiedHTTPSConnection object at 0x0000027B975BC608>, 'Connection to 61.160.245.88 timed out. (connect timeout=5)'))
2020-05-15 14:18:20,704 - xici_ip_model.py[line:31] - INFO: ('start get 1 page', 'https://www.xicidaili.com/nn/8.html')
2020-05-15 14:18:25,706 - xici_ip_model.py[line:47] - ERROR: HTTPSConnectionPool(host='www.xicidaili.com', port=443): Max retries exceeded with url: /nn/8.html (Caused by ConnectTimeoutError(<urllib3.connection.VerifiedHTTPSConnection object at 0x0000027B975CA748>, 'Connection to 61.160.245.88 timed out. (connect timeout=5)'))
2020-05-15 14:18:25,707 - xici_ip_model.py[line:31] - INFO: ('start get 1 page', 'https://www.xicidaili.com/nn/9.html')
2020-05-15 14:18:33,362 - redis_memory.py[line:68] - INFO: ('flush', 'xici:xici_proxy_queue', 'exp', 600, 'remove count', 0)
2020-05-15 14:18:37,366 - redis_memory.py[line:68] - INFO: ('flush', 'xici:xici_proxy_queue', 'exp', 600, 'remove count', 0)
2020-05-15 14:18:41,369 - redis_memory.py[line:68] - INFO: ('flush', 'xici:xici_proxy_queue', 'exp', 600, 'remove count', 0)
2020-05-15 14:18:45,376 - redis_memory.py[line:68] - INFO: ('flush', 'xici:xici_proxy_queue', 'exp', 600, 'remove count', 0)
2020-05-15 14:18:49,381 - redis_memory.py[line:68] - INFO: ('flush', 'xici:xici_proxy_queue', 'exp', 600, 'remove count', 0)
2020-05-15 14:18:53,384 - redis_memory.py[line:68] - INFO: ('flush', 'xici:xici_proxy_queue', 'exp', 600, 'remove count', 0)
2020-05-15 14:18:57,389 - redis_memory.py[line:68] - INFO: ('flush', 'xici:xici_proxy_queue', 'exp', 600, 'remove count', 0)
2020-05-15 14:19:01,393 - redis_memory.py[line:68] - INFO: ('flush', 'xici:xici_proxy_queue', 'exp', 600, 'remove count', 0)
2020-05-15 14:19:05,399 - redis_memory.py[line:68] - INFO: ('flush', 'xici:xici_proxy_queue', 'exp', 600, 'remove count', 0)
2020-05-15 14:19:09,403 - redis_memory.py[line:68] - INFO: ('flush', 'xici:xici_proxy_queue', 'exp', 600, 'remove count', 0)
2020-05-15 14:19:13,409 - redis_memory.py[line:68] - INFO: ('flush', 'xici:xici_proxy_queue', 'exp', 600, 'remove count', 0)
2020-05-15 14:19:17,414 - redis_memory.py[line:68] - INFO: ('flush', 'xici:xici_proxy_queue', 'exp', 600, 'remove count', 0)
2020-05-15 14:19:21,418 - redis_memory.py[line:68] - INFO: ('flush', 'xici:xici_proxy_queue', 'exp', 600, 'remove count', 0)
2020-05-15 14:19:25,423 - redis_memory.py[line:68] - INFO: ('flush', 'xici:xici_proxy_queue', 'exp', 600, 'remove count', 0)
2020-05-15 14:19:29,428 - redis_memory.py[line:68] - INFO: ('flush', 'xici:xici_proxy_queue', 'exp', 600, 'remove count', 0)
2020-05-15 14:19:33,433 - redis_memory.py[line:68] - INFO: ('flush', 'xici:xici_proxy_queue', 'exp', 600, 'remove count', 0)
2020-05-15 14:19:37,436 - redis_memory.py[line:68] - INFO: ('flush', 'xici:xici_proxy_queue', 'exp', 600, 'remove count', 0)
2020-05-15 14:19:41,443 - redis_memory.py[line:68] - INFO: ('flush', 'xici:xici_proxy_queue', 'exp', 600, 'remove count', 0)
2020-05-15 14:19:45,449 - redis_memory.py[line:68] - INFO: ('flush', 'xici:xici_proxy_queue', 'exp', 600, 'remove count', 0)
2020-05-15 14:19:49,454 - redis_memory.py[line:68] - INFO: ('flush', 'xici:xici_proxy_queue', 'exp', 600, 'remove count', 0)
2020-05-15 14:19:53,458 - redis_memory.py[line:68] - INFO: ('flush', 'xici:xici_proxy_queue', 'exp', 600, 'remove count', 0)
2020-05-15 14:19:57,461 - redis_memory.py[line:68] - INFO: ('flush', 'xici:xici_proxy_queue', 'exp', 600, 'remove count', 0)
2020-05-15 14:20:01,467 - redis_memory.py[line:68] - INFO: ('flush', 'xici:xici_proxy_queue', 'exp', 600, 'remove count', 0)
2020-05-15 14:20:05,472 - redis_memory.py[line:68] - INFO: ('flush', 'xici:xici_proxy_queue', 'exp', 600, 'remove count', 0)
2020-05-15 14:20:09,478 - redis_memory.py[line:68] - INFO: ('flush', 'xici:xici_proxy_queue', 'exp', 600, 'remove count', 0)
2020-05-15 14:20:13,483 - redis_memory.py[line:68] - INFO: ('flush', 'xici:xici_proxy_queue', 'exp', 600, 'remove count', 0)
2020-05-15 14:20:17,486 - redis_memory.py[line:68] - INFO: ('flush', 'xici:xici_proxy_queue', 'exp', 600, 'remove count', 0)
2020-05-15 14:20:21,490 - redis_memory.py[line:68] - INFO: ('flush', 'xici:xici_proxy_queue', 'exp', 600, 'remove count', 0)
2020-05-15 14:20:25,496 - redis_memory.py[line:68] - INFO: ('flush', 'xici:xici_proxy_queue', 'exp', 600, 'remove count', 0)
2020-05-15 14:20:29,502 - redis_memory.py[line:68] - INFO: ('flush', 'xici:xici_proxy_queue', 'exp', 600, 'remove count', 0)
2020-05-15 14:20:33,508 - redis_memory.py[line:68] - INFO: ('flush', 'xici:xici_proxy_queue', 'exp', 600, 'remove count', 0)
2020-05-15 14:20:37,511 - redis_memory.py[line:68] - INFO: ('flush', 'xici:xici_proxy_queue', 'exp', 600, 'remove count', 0)
2020-05-15 14:20:41,514 - redis_memory.py[line:68] - INFO: ('flush', 'xici:xici_proxy_queue', 'exp', 600, 'remove count', 0)
2020-05-15 14:20:45,519 - redis_memory.py[line:68] - INFO: ('flush', 'xici:xici_proxy_queue', 'exp', 600, 'remove count', 0)
2020-05-15 14:20:49,522 - redis_memory.py[line:68] - INFO: ('flush', 'xici:xici_proxy_queue', 'exp', 600, 'remove count', 0)
2020-05-15 14:20:53,526 - redis_memory.py[line:68] - INFO: ('flush', 'xici:xici_proxy_queue', 'exp', 600, 'remove count', 0)
2020-05-15 14:20:57,530 - redis_memory.py[line:68] - INFO: ('flush', 'xici:xici_proxy_queue', 'exp', 600, 'remove count', 0)
2020-05-15 14:21:01,534 - redis_memory.py[line:68] - INFO: ('flush', 'xici:xici_proxy_queue', 'exp', 600, 'remove count', 0)
2020-05-15 14:21:05,537 - redis_memory.py[line:68] - INFO: ('flush', 'xici:xici_proxy_queue', 'exp', 600, 'remove count', 0)
2020-05-15 14:21:09,543 - redis_memory.py[line:68] - INFO: ('flush', 'xici:xici_proxy_queue', 'exp', 600, 'remove count', 0)
2020-05-15 14:21:13,546 - redis_memory.py[line:68] - INFO: ('flush', 'xici:xici_proxy_queue', 'exp', 600, 'remove count', 0)
2020-05-15 14:21:17,551 - redis_memory.py[line:68] - INFO: ('flush', 'xici:xici_proxy_queue', 'exp', 600, 'remove count', 0)
2020-05-15 14:21:21,555 - redis_memory.py[line:68] - INFO: ('flush', 'xici:xici_proxy_queue', 'exp', 600, 'remove count', 0)
2020-05-15 14:21:25,560 - redis_memory.py[line:68] - INFO: ('flush', 'xici:xici_proxy_queue', 'exp', 600, 'remove count', 0)
2020-05-15 14:21:29,566 - redis_memory.py[line:68] - INFO: ('flush', 'xici:xici_proxy_queue', 'exp', 600, 'remove count', 0)
2020-05-15 14:21:33,570 - redis_memory.py[line:68] - INFO: ('flush', 'xici:xici_proxy_queue', 'exp', 600, 'remove count', 0)
2020-05-15 14:21:37,575 - redis_memory.py[line:68] - INFO: ('flush', 'xici:xici_proxy_queue', 'exp', 600, 'remove count', 0)
2020-05-15 14:21:41,578 - redis_memory.py[line:68] - INFO: ('flush', 'xici:xici_proxy_queue', 'exp', 600, 'remove count', 0)
2020-05-15 14:21:45,582 - redis_memory.py[line:68] - INFO: ('flush', 'xici:xici_proxy_queue', 'exp', 600, 'remove count', 0)
2020-05-15 14:21:49,585 - redis_memory.py[line:68] - INFO: ('flush', 'xici:xici_proxy_queue', 'exp', 600, 'remove count', 0)
2020-05-15 14:21:53,594 - redis_memory.py[line:68] - INFO: ('flush', 'xici:xici_proxy_queue', 'exp', 600, 'remove count', 0)
2020-05-15 14:21:57,598 - redis_memory.py[line:68] - INFO: ('flush', 'xici:xici_proxy_queue', 'exp', 600, 'remove count', 0)
2020-05-15 14:22:01,604 - redis_memory.py[line:68] - INFO: ('flush', 'xici:xici_proxy_queue', 'exp', 600, 'remove count', 0)
2020-05-15 14:22:05,608 - redis_memory.py[line:68] - INFO: ('flush', 'xici:xici_proxy_queue', 'exp', 600, 'remove count', 0)
2020-05-15 14:22:09,614 - redis_memory.py[line:68] - INFO: ('flush', 'xici:xici_proxy_queue', 'exp', 600, 'remove count', 99)
2020-05-15 14:22:13,617 - redis_memory.py[line:64] - INFO: ('set row', '115.196.195.120:8060')
2020-05-15 14:22:13,619 - redis_memory.py[line:64] - INFO: ('set row', '117.88.177.32:3000')
2020-05-15 14:22:13,622 - redis_memory.py[line:64] - INFO: ('set row', '101.132.190.101:80')
2020-05-15 14:22:13,623 - redis_memory.py[line:64] - INFO: ('set row', '117.88.176.170:3000')
2020-05-15 14:22:13,625 - redis_memory.py[line:64] - INFO: ('set row', '117.88.176.42:3000')
2020-05-15 14:22:13,627 - redis_memory.py[line:64] - INFO: ('set row', '117.88.176.134:3000')
2020-05-15 14:22:13,629 - redis_memory.py[line:64] - INFO: ('set row', '222.95.144.87:3000')
2020-05-15 14:22:13,631 - redis_memory.py[line:64] - INFO: ('set row', '27.184.123.176:8118')
2020-05-15 14:22:13,633 - redis_memory.py[line:64] - INFO: ('set row', '121.237.148.193:3000')
2020-05-15 14:22:13,635 - redis_memory.py[line:64] - INFO: ('set row', '219.143.207.45:800')
2020-05-15 14:22:13,636 - redis_memory.py[line:64] - INFO: ('set row', '106.15.126.137:8080')
2020-05-15 14:22:13,638 - redis_memory.py[line:64] - INFO: ('set row', '182.96.158.55:8118')
2020-05-15 14:22:13,640 - redis_memory.py[line:64] - INFO: ('set row', '114.104.17.178:10098')
2020-05-15 14:22:13,641 - redis_memory.py[line:64] - INFO: ('set row', '115.204.198.148:8118')
2020-05-15 14:22:13,643 - redis_memory.py[line:64] - INFO: ('set row', '121.8.146.99:8060')
2020-05-15 14:22:13,645 - redis_memory.py[line:64] - INFO: ('set row', '117.88.177.93:3000')
2020-05-15 14:22:13,647 - redis_memory.py[line:64] - INFO: ('set row', '111.76.168.201:8118')
2020-05-15 14:22:13,648 - redis_memory.py[line:64] - INFO: ('set row', '221.182.89.234:63000')
2020-05-15 14:22:13,651 - redis_memory.py[line:64] - INFO: ('set row', '117.88.176.229:3000')
2020-05-15 14:22:13,653 - redis_memory.py[line:64] - INFO: ('set row', '60.184.196.213:8888')
2020-05-15 14:22:13,655 - redis_memory.py[line:64] - INFO: ('set row', '183.166.171.252:61234')
2020-05-15 14:22:13,658 - redis_memory.py[line:64] - INFO: ('set row', '125.40.11.183:8118')
2020-05-15 14:22:13,660 - redis_memory.py[line:64] - INFO: ('set row', '175.148.77.47:1133')
2020-05-15 14:22:13,663 - redis_memory.py[line:64] - INFO: ('set row', '222.95.144.68:3000')
2020-05-15 14:22:13,664 - redis_memory.py[line:64] - INFO: ('set row', '175.148.78.181:1133')
2020-05-15 14:22:13,666 - redis_memory.py[line:64] - INFO: ('set row', '117.88.4.91:3000')
2020-05-15 14:22:13,668 - redis_memory.py[line:64] - INFO: ('set row', '121.237.148.211:3000')
2020-05-15 14:22:13,671 - redis_memory.py[line:64] - INFO: ('set row', '222.95.144.189:3000')
2020-05-15 14:22:13,673 - redis_memory.py[line:64] - INFO: ('set row', '121.237.148.155:3000')
2020-05-15 14:22:13,674 - redis_memory.py[line:64] - INFO: ('set row', '117.88.5.197:3000')
2020-05-15 14:22:13,677 - redis_memory.py[line:64] - INFO: ('set row', '115.221.240.171:9999')
2020-05-15 14:22:13,679 - redis_memory.py[line:64] - INFO: ('set row', '117.88.5.241:3000')
2020-05-15 14:22:13,680 - redis_memory.py[line:64] - INFO: ('set row', '117.88.177.86:3000')
2020-05-15 14:22:13,684 - redis_memory.py[line:64] - INFO: ('set row', '171.35.163.6:9999')
2020-05-15 14:22:13,685 - redis_memory.py[line:64] - INFO: ('set row', '114.99.0.211:808')
2020-05-15 14:22:13,687 - redis_memory.py[line:64] - INFO: ('set row', '113.195.171.75:9999')
2020-05-15 14:22:13,690 - redis_memory.py[line:64] - INFO: ('set row', '222.95.144.121:3000')
2020-05-15 14:22:13,693 - redis_memory.py[line:64] - INFO: ('set row', '117.88.5.116:3000')
2020-05-15 14:22:13,697 - redis_memory.py[line:64] - INFO: ('set row', '118.24.118.207:808')
2020-05-15 14:22:13,701 - redis_memory.py[line:64] - INFO: ('set row', '112.192.34.47:1133')
2020-05-15 14:22:13,705 - redis_memory.py[line:64] - INFO: ('set row', '171.35.166.86:9999')
2020-05-15 14:22:13,709 - redis_memory.py[line:64] - INFO: ('set row', '110.243.8.26:9999')
2020-05-15 14:22:13,713 - redis_memory.py[line:64] - INFO: ('set row', '60.217.129.63:8060')
2020-05-15 14:22:13,717 - redis_memory.py[line:64] - INFO: ('set row', '139.196.193.85:8080')
2020-05-15 14:22:13,721 - redis_memory.py[line:64] - INFO: ('set row', '123.171.5.124:8118')
2020-05-15 14:22:13,724 - redis_memory.py[line:64] - INFO: ('set row', '175.148.71.139:1133')
2020-05-15 14:22:13,727 - redis_memory.py[line:64] - INFO: ('set row', '114.223.208.165:8118')
2020-05-15 14:22:13,730 - redis_memory.py[line:64] - INFO: ('set row', '114.226.35.175:8118')
2020-05-15 14:22:13,732 - redis_memory.py[line:64] - INFO: ('set row', '175.148.69.176:1133')
2020-05-15 14:22:13,734 - redis_memory.py[line:64] - INFO: ('set row', '175.43.35.39:9999')
2020-05-15 14:22:13,737 - redis_memory.py[line:64] - INFO: ('set row', '114.226.160.141:9999')
2020-05-15 14:22:13,739 - redis_memory.py[line:64] - INFO: ('set row', '113.195.225.130:9999')
2020-05-15 14:22:13,742 - redis_memory.py[line:64] - INFO: ('set row', '182.61.12.214:8888')
2020-05-15 14:22:13,744 - redis_memory.py[line:64] - INFO: ('set row', '113.194.30.80:9999')
2020-05-15 14:22:13,747 - redis_memory.py[line:64] - INFO: ('set row', '183.166.170.208:8888')
2020-05-15 14:22:13,749 - redis_memory.py[line:64] - INFO: ('set row', '117.88.5.253:3000')
2020-05-15 14:22:13,752 - redis_memory.py[line:64] - INFO: ('set row', '60.31.213.115:808')
2020-05-15 14:22:13,755 - redis_memory.py[line:64] - INFO: ('set row', '171.35.147.251:9999')
2020-05-15 14:22:13,758 - redis_memory.py[line:64] - INFO: ('set row', '144.123.70.205:10086')
2020-05-15 14:22:13,760 - redis_memory.py[line:64] - INFO: ('set row', '121.237.148.106:3000')
2020-05-15 14:22:13,763 - redis_memory.py[line:64] - INFO: ('set row', '117.88.5.246:3000')
2020-05-15 14:22:13,766 - redis_memory.py[line:64] - INFO: ('set row', '110.243.10.182:9999')
2020-05-15 14:22:13,769 - redis_memory.py[line:64] - INFO: ('set row', '49.70.18.179:61234')
2020-05-15 14:22:13,772 - redis_memory.py[line:64] - INFO: ('set row', '121.237.149.66:3000')
2020-05-15 14:22:13,775 - redis_memory.py[line:64] - INFO: ('set row', '60.167.112.199:1133')
2020-05-15 14:22:13,779 - redis_memory.py[line:64] - INFO: ('set row', '121.237.148.101:3000')
2020-05-15 14:22:13,782 - redis_memory.py[line:64] - INFO: ('set row', '221.193.94.18:8118')
2020-05-15 14:22:13,785 - redis_memory.py[line:64] - INFO: ('set row', '121.237.148.183:3000')
2020-05-15 14:22:13,787 - redis_memory.py[line:64] - INFO: ('set row', '171.11.33.58:9999')
2020-05-15 14:22:13,790 - redis_memory.py[line:64] - INFO: ('set row', '113.194.28.11:9999')
2020-05-15 14:22:13,793 - redis_memory.py[line:64] - INFO: ('set row', '113.195.168.115:48888')
2020-05-15 14:22:13,796 - redis_memory.py[line:64] - INFO: ('set row', '118.113.247.115:9999')
2020-05-15 14:22:13,798 - redis_memory.py[line:64] - INFO: ('set row', '60.167.112.236:1133')
2020-05-15 14:22:13,801 - redis_memory.py[line:64] - INFO: ('set row', '117.88.177.101:3000')
2020-05-15 14:22:13,804 - redis_memory.py[line:64] - INFO: ('set row', '183.166.136.144:8888')
2020-05-15 14:22:13,807 - redis_memory.py[line:64] - INFO: ('set row', '27.208.231.100:8060')
2020-05-15 14:22:13,810 - redis_memory.py[line:64] - INFO: ('set row', '123.169.99.177:9999')
2020-05-15 14:22:13,813 - redis_memory.py[line:64] - INFO: ('set row', '119.4.13.26:1133')
2020-05-15 14:22:13,815 - redis_memory.py[line:64] - INFO: ('set row', '58.253.158.177:9999')
2020-05-15 14:22:13,818 - redis_memory.py[line:64] - INFO: ('set row', '112.84.73.53:9999')
2020-05-15 14:22:13,822 - redis_memory.py[line:64] - INFO: ('set row', '221.237.37.137:8118')
2020-05-15 14:22:13,824 - redis_memory.py[line:64] - INFO: ('set row', '117.45.139.84:9006')
2020-05-15 14:22:13,827 - redis_memory.py[line:64] - INFO: ('set row', '171.35.86.72:8118')
2020-05-15 14:22:13,830 - redis_memory.py[line:64] - INFO: ('set row', '49.235.246.24:8118')
2020-05-15 14:22:13,834 - redis_memory.py[line:64] - INFO: ('set row', '60.188.65.73:3000')
2020-05-15 14:22:13,836 - redis_memory.py[line:64] - INFO: ('set row', '175.148.69.26:1133')
2020-05-15 14:22:13,839 - redis_memory.py[line:64] - INFO: ('set row', '183.166.103.164:9999')
2020-05-15 14:22:13,842 - redis_memory.py[line:64] - INFO: ('set row', '113.195.225.68:9999')
2020-05-15 14:22:13,845 - redis_memory.py[line:64] - INFO: ('set row', '117.88.176.123:3000')
2020-05-15 14:22:13,848 - redis_memory.py[line:64] - INFO: ('set row', '175.148.68.175:1133')
2020-05-15 14:22:13,852 - redis_memory.py[line:64] - INFO: ('set row', '171.35.163.132:9999')
2020-05-15 14:22:13,855 - redis_memory.py[line:64] - INFO: ('set row', '117.88.177.24:3000')
2020-05-15 14:22:13,858 - redis_memory.py[line:64] - INFO: ('set row', '121.237.148.135:3000')
2020-05-15 14:22:13,861 - redis_memory.py[line:64] - INFO: ('set row', '121.237.149.220:3000')
2020-05-15 14:22:13,864 - redis_memory.py[line:64] - INFO: ('set row', '110.243.5.40:9999')
2020-05-15 14:22:13,867 - redis_memory.py[line:64] - INFO: ('set row', '122.4.40.194:27430')
2020-05-15 14:22:13,870 - redis_memory.py[line:64] - INFO: ('set row', '115.49.74.102:8118')
2020-05-15 14:22:13,873 - redis_memory.py[line:64] - INFO: ('set row', '101.200.81.61:80')
2020-05-15 14:22:13,876 - redis_memory.py[line:64] - INFO: ('set row', '49.76.237.243:8123')
2020-05-15 14:22:13,879 - redis_memory.py[line:68] - INFO: ('flush', 'xici:xici_proxy_queue', 'exp', 600, 'remove count', 1)
2020-05-15 14:22:17,883 - redis_memory.py[line:64] - INFO: ('set row', '117.88.176.221:3000')
2020-05-15 14:22:17,884 - xici_ip_model.py[line:31] - INFO: ('start get 1 page', 'https://www.xicidaili.com/nn/10.html')
2020-05-15 14:22:22,887 - xici_ip_model.py[line:47] - ERROR: HTTPSConnectionPool(host='www.xicidaili.com', port=443): Max retries exceeded with url: /nn/10.html (Caused by ConnectTimeoutError(<urllib3.connection.VerifiedHTTPSConnection object at 0x0000027B975D0548>, 'Connection to 61.160.245.88 timed out. (connect timeout=5)'))
2020-05-15 14:22:22,888 - xici_ip_model.py[line:31] - INFO: ('start get 1 page', 'https://www.xicidaili.com/nn/11.html')
2020-05-15 14:22:27,890 - xici_ip_model.py[line:47] - ERROR: HTTPSConnectionPool(host='www.xicidaili.com', port=443): Max retries exceeded with url: /nn/11.html (Caused by ConnectTimeoutError(<urllib3.connection.VerifiedHTTPSConnection object at 0x0000027B975CA608>, 'Connection to 61.160.245.88 timed out. (connect timeout=5)'))
2020-05-15 14:22:27,891 - xici_ip_model.py[line:31] - INFO: ('start get 1 page', 'https://www.xicidaili.com/nn/12.html')
2020-05-15 14:22:32,892 - xici_ip_model.py[line:47] - ERROR: HTTPSConnectionPool(host='www.xicidaili.com', port=443): Max retries exceeded with url: /nn/12.html (Caused by ConnectTimeoutError(<urllib3.connection.VerifiedHTTPSConnection object at 0x0000027B974BFC08>, 'Connection to 61.160.245.88 timed out. (connect timeout=5)'))
2020-05-15 14:22:32,892 - xici_ip_model.py[line:31] - INFO: ('start get 1 page', 'https://www.xicidaili.com/nn/13.html')
2020-05-15 14:22:37,895 - xici_ip_model.py[line:47] - ERROR: HTTPSConnectionPool(host='www.xicidaili.com', port=443): Max retries exceeded with url: /nn/13.html (Caused by ConnectTimeoutError(<urllib3.connection.VerifiedHTTPSConnection object at 0x0000027B975BC408>, 'Connection to 61.160.245.88 timed out. (connect timeout=5)'))
2020-05-15 14:22:37,896 - xici_ip_model.py[line:31] - INFO: ('start get 1 page', 'https://www.xicidaili.com/nn/14.html')
2020-05-15 14:22:42,897 - xici_ip_model.py[line:47] - ERROR: HTTPSConnectionPool(host='www.xicidaili.com', port=443): Max retries exceeded with url: /nn/14.html (Caused by ConnectTimeoutError(<urllib3.connection.VerifiedHTTPSConnection object at 0x0000027B9749FF88>, 'Connection to 61.160.245.88 timed out. (connect timeout=5)'))
2020-05-15 14:22:42,898 - xici_ip_model.py[line:31] - INFO: ('start get 1 page', 'https://www.xicidaili.com/nn/15.html')
2020-05-15 14:22:47,900 - xici_ip_model.py[line:47] - ERROR: HTTPSConnectionPool(host='www.xicidaili.com', port=443): Max retries exceeded with url: /nn/15.html (Caused by ConnectTimeoutError(<urllib3.connection.VerifiedHTTPSConnection object at 0x0000027B975B9448>, 'Connection to 61.160.245.88 timed out. (connect timeout=5)'))
2020-05-15 14:22:47,901 - xici_ip_model.py[line:31] - INFO: ('start get 1 page', 'https://www.xicidaili.com/nn/16.html')
2020-05-15 14:22:55,974 - xici_ip_model.py[line:43] - ERROR: ('proxy err', ProxyError(MaxRetryError("HTTPSConnectionPool(host='www.xicidaili.com', port=443): Max retries exceeded with url: /nn/16.html (Caused by ProxyError('Cannot connect to proxy.', timeout('timed out')))")))
2020-05-15 14:22:55,976 - xici_ip_model.py[line:31] - INFO: ('start get 1 page', 'https://www.xicidaili.com/nn/17.html')
2020-05-15 14:22:56,081 - xici_ip_model.py[line:43] - ERROR: ('proxy err', ProxyError(MaxRetryError("HTTPSConnectionPool(host='www.xicidaili.com', port=443): Max retries exceeded with url: /nn/17.html (Caused by ProxyError('Cannot connect to proxy.', RemoteDisconnected('Remote end closed connection without response')))")))
2020-05-15 14:22:56,088 - xici_ip_model.py[line:31] - INFO: ('start get 1 page', 'https://www.xicidaili.com/nn/18.html')
2020-05-15 14:23:01,091 - xici_ip_model.py[line:47] - ERROR: HTTPSConnectionPool(host='www.xicidaili.com', port=443): Max retries exceeded with url: /nn/18.html (Caused by ConnectTimeoutError(<urllib3.connection.VerifiedHTTPSConnection object at 0x0000027B975B9548>, 'Connection to 27.188.64.70 timed out. (connect timeout=5)'))
2020-05-15 14:23:01,092 - xici_ip_model.py[line:31] - INFO: ('start get 1 page', 'https://www.xicidaili.com/nn/19.html')
2020-05-15 14:23:04,193 - xici_ip_model.py[line:47] - ERROR: ('Connection aborted.', BadStatusLine('<html>\r\n'))
2020-05-15 14:23:04,194 - xici_ip_model.py[line:31] - INFO: ('start get 1 page', 'https://www.xicidaili.com/nn/20.html')
2020-05-15 14:23:09,195 - xici_ip_model.py[line:47] - ERROR: HTTPSConnectionPool(host='www.xicidaili.com', port=443): Max retries exceeded with url: /nn/20.html (Caused by ConnectTimeoutError(<urllib3.connection.VerifiedHTTPSConnection object at 0x0000027B975B5448>, 'Connection to 27.188.64.70 timed out. (connect timeout=5)'))
2020-05-15 14:23:09,198 - xici_ip_model.py[line:31] - INFO: ('start get 1 page', 'https://www.xicidaili.com/nn/21.html')
2020-05-15 14:23:09,302 - xici_ip_model.py[line:47] - ERROR: ('Connection aborted.', BadStatusLine('<html>\r\n'))
2020-05-15 14:23:09,303 - xici_ip_model.py[line:31] - INFO: ('start get 1 page', 'https://www.xicidaili.com/nn/22.html')
2020-05-15 14:23:14,305 - xici_ip_model.py[line:47] - ERROR: HTTPSConnectionPool(host='www.xicidaili.com', port=443): Max retries exceeded with url: /nn/22.html (Caused by ConnectTimeoutError(<urllib3.connection.VerifiedHTTPSConnection object at 0x0000027B975BC388>, 'Connection to 27.188.64.70 timed out. (connect timeout=5)'))
2020-05-15 14:23:14,306 - xici_ip_model.py[line:31] - INFO: ('start get 1 page', 'https://www.xicidaili.com/nn/23.html')
2020-05-15 14:23:19,308 - xici_ip_model.py[line:47] - ERROR: HTTPSConnectionPool(host='www.xicidaili.com', port=443): Max retries exceeded with url: /nn/23.html (Caused by ConnectTimeoutError(<urllib3.connection.VerifiedHTTPSConnection object at 0x0000027B975AD788>, 'Connection to 27.188.64.70 timed out. (connect timeout=5)'))
2020-05-15 14:23:19,309 - xici_ip_model.py[line:31] - INFO: ('start get 1 page', 'https://www.xicidaili.com/nn/24.html')
2020-05-15 14:23:22,397 - xici_ip_model.py[line:43] - ERROR: ('proxy err', ProxyError(MaxRetryError("HTTPSConnectionPool(host='www.xicidaili.com', port=443): Max retries exceeded with url: /nn/24.html (Caused by ProxyError('Cannot connect to proxy.', ConnectionResetError(10054, '远程主机强迫关闭了一个现有的连接。', None, 10054, None)))")))
2020-05-15 14:23:22,400 - xici_ip_model.py[line:31] - INFO: ('start get 1 page', 'https://www.xicidaili.com/nn/25.html')
2020-05-15 14:23:27,402 - xici_ip_model.py[line:47] - ERROR: HTTPSConnectionPool(host='www.xicidaili.com', port=443): Max retries exceeded with url: /nn/25.html (Caused by ConnectTimeoutError(<urllib3.connection.VerifiedHTTPSConnection object at 0x0000027B975CAB48>, 'Connection to 121.33.220.158 timed out. (connect timeout=5)'))
2020-05-15 14:23:27,403 - xici_ip_model.py[line:31] - INFO: ('start get 1 page', 'https://www.xicidaili.com/nn/26.html')
2020-05-15 14:23:32,426 - xici_ip_model.py[line:47] - ERROR: HTTPSConnectionPool(host='www.xicidaili.com', port=443): Max retries exceeded with url: /nn/26.html (Caused by ConnectTimeoutError(<urllib3.connection.VerifiedHTTPSConnection object at 0x0000027B974BFCC8>, 'Connection to 121.33.220.158 timed out. (connect timeout=5)'))
2020-05-15 14:23:32,453 - xici_ip_model.py[line:31] - INFO: ('start get 1 page', 'https://www.xicidaili.com/nn/27.html')
2020-05-15 14:23:37,461 - xici_ip_model.py[line:47] - ERROR: HTTPSConnectionPool(host='www.xicidaili.com', port=443): Max retries exceeded with url: /nn/27.html (Caused by ConnectTimeoutError(<urllib3.connection.VerifiedHTTPSConnection object at 0x0000027B975B9BC8>, 'Connection to 121.33.220.158 timed out. (connect timeout=5)'))
2020-05-15 14:23:37,462 - xici_ip_model.py[line:31] - INFO: ('start get 1 page', 'https://www.xicidaili.com/nn/28.html')
2020-05-15 14:23:42,463 - xici_ip_model.py[line:47] - ERROR: HTTPSConnectionPool(host='www.xicidaili.com', port=443): Max retries exceeded with url: /nn/28.html (Caused by ConnectTimeoutError(<urllib3.connection.VerifiedHTTPSConnection object at 0x0000027B975BCDC8>, 'Connection to 121.33.220.158 timed out. (connect timeout=5)'))
2020-05-15 14:23:42,464 - xici_ip_model.py[line:31] - INFO: ('start get 1 page', 'https://www.xicidaili.com/nn/29.html')
2020-05-15 14:23:47,608 - xici_ip_model.py[line:47] - ERROR: HTTPSConnectionPool(host='www.xicidaili.com', port=443): Max retries exceeded with url: /nn/29.html (Caused by ConnectTimeoutError(<urllib3.connection.VerifiedHTTPSConnection object at 0x0000027B975AC348>, 'Connection to 121.33.220.158 timed out. (connect timeout=5)'))
2020-05-15 14:23:47,609 - xici_ip_model.py[line:31] - INFO: ('start get 1 page', 'https://www.xicidaili.com/nn/30.html')
2020-05-15 14:23:52,611 - xici_ip_model.py[line:47] - ERROR: HTTPSConnectionPool(host='www.xicidaili.com', port=443): Max retries exceeded with url: /nn/30.html (Caused by ConnectTimeoutError(<urllib3.connection.VerifiedHTTPSConnection object at 0x0000027B975B50C8>, 'Connection to 121.33.220.158 timed out. (connect timeout=5)'))
2020-05-15 14:23:52,612 - xici_ip_model.py[line:31] - INFO: ('start get 1 page', 'https://www.xicidaili.com/nn/31.html')
2020-05-15 14:23:57,626 - xici_ip_model.py[line:47] - ERROR: HTTPSConnectionPool(host='www.xicidaili.com', port=443): Max retries exceeded with url: /nn/31.html (Caused by ConnectTimeoutError(<urllib3.connection.VerifiedHTTPSConnection object at 0x0000027B975D0048>, 'Connection to 121.33.220.158 timed out. (connect timeout=5)'))
2020-05-15 14:23:57,627 - xici_ip_model.py[line:31] - INFO: ('start get 1 page', 'https://www.xicidaili.com/nn/32.html')
2020-05-15 14:24:02,630 - xici_ip_model.py[line:47] - ERROR: HTTPSConnectionPool(host='www.xicidaili.com', port=443): Max retries exceeded with url: /nn/32.html (Caused by ConnectTimeoutError(<urllib3.connection.VerifiedHTTPSConnection object at 0x0000027B975CA548>, 'Connection to 121.33.220.158 timed out. (connect timeout=5)'))
2020-05-15 14:24:02,631 - xici_ip_model.py[line:31] - INFO: ('start get 1 page', 'https://www.xicidaili.com/nn/33.html')
2020-05-15 14:24:07,633 - xici_ip_model.py[line:47] - ERROR: HTTPSConnectionPool(host='www.xicidaili.com', port=443): Max retries exceeded with url: /nn/33.html (Caused by ConnectTimeoutError(<urllib3.connection.VerifiedHTTPSConnection object at 0x0000027B975B5548>, 'Connection to 121.33.220.158 timed out. (connect timeout=5)'))
2020-05-15 14:24:07,633 - xici_ip_model.py[line:31] - INFO: ('start get 1 page', 'https://www.xicidaili.com/nn/34.html')
2020-05-15 14:24:11,072 - xici_ip_model.py[line:31] - INFO: ('start get 1 page', 'https://www.xicidaili.com/nn/35.html')
2020-05-15 14:24:12,177 - xici_ip_model.py[line:43] - ERROR: ('proxy err', ProxyError(MaxRetryError("HTTPSConnectionPool(host='www.xicidaili.com', port=443): Max retries exceeded with url: /nn/35.html (Caused by ProxyError('Cannot connect to proxy.', OSError('Tunnel connection failed: 503 Too many open connections')))")))
2020-05-15 14:27:38,567 - xici_ip_model.py[line:31] - INFO: ('start get 1 page', 'https://www.xicidaili.com/nn/1.html')
2020-05-15 14:27:38,869 - xici_ip_model.py[line:47] - ERROR: stack is empty
2020-05-15 14:27:38,870 - xici_ip_model.py[line:31] - INFO: ('start get 1 page', 'https://www.xicidaili.com/nn/2.html')
2020-05-15 14:27:39,165 - xici_ip_model.py[line:47] - ERROR: stack is empty
2020-05-15 14:27:39,166 - xici_ip_model.py[line:31] - INFO: ('start get 1 page', 'https://www.xicidaili.com/nn/3.html')
2020-05-15 14:27:39,457 - xici_ip_model.py[line:47] - ERROR: stack is empty
2020-05-15 14:27:39,460 - xici_ip_model.py[line:31] - INFO: ('start get 1 page', 'https://www.xicidaili.com/nn/4.html')
2020-05-15 14:27:39,733 - xici_ip_model.py[line:47] - ERROR: stack is empty
2020-05-15 14:27:39,734 - xici_ip_model.py[line:31] - INFO: ('start get 1 page', 'https://www.xicidaili.com/nn/5.html')
2020-05-15 14:27:40,006 - xici_ip_model.py[line:47] - ERROR: stack is empty
2020-05-15 14:27:40,008 - xici_ip_model.py[line:31] - INFO: ('start get 1 page', 'https://www.xicidaili.com/nn/6.html')
2020-05-15 14:27:40,260 - xici_ip_model.py[line:47] - ERROR: stack is empty
2020-05-15 14:27:40,261 - xici_ip_model.py[line:31] - INFO: ('start get 1 page', 'https://www.xicidaili.com/nn/7.html')
2020-05-15 14:27:40,532 - xici_ip_model.py[line:47] - ERROR: stack is empty
2020-05-15 14:27:40,532 - xici_ip_model.py[line:31] - INFO: ('start get 1 page', 'https://www.xicidaili.com/nn/8.html')
2020-05-15 14:27:40,784 - xici_ip_model.py[line:47] - ERROR: stack is empty
2020-05-15 14:27:40,785 - xici_ip_model.py[line:31] - INFO: ('start get 1 page', 'https://www.xicidaili.com/nn/9.html')
2020-05-15 14:27:41,072 - xici_ip_model.py[line:47] - ERROR: stack is empty
2020-05-15 14:27:41,074 - xici_ip_model.py[line:31] - INFO: ('start get 1 page', 'https://www.xicidaili.com/nn/10.html')
2020-05-15 14:27:41,332 - xici_ip_model.py[line:47] - ERROR: stack is empty
2020-05-15 14:27:41,333 - xici_ip_model.py[line:31] - INFO: ('start get 1 page', 'https://www.xicidaili.com/nn/11.html')
2020-05-15 14:27:41,583 - xici_ip_model.py[line:47] - ERROR: stack is empty
2020-05-15 14:27:41,583 - xici_ip_model.py[line:31] - INFO: ('start get 1 page', 'https://www.xicidaili.com/nn/12.html')
2020-05-15 14:27:41,869 - xici_ip_model.py[line:47] - ERROR: stack is empty
2020-05-15 14:27:41,870 - xici_ip_model.py[line:31] - INFO: ('start get 1 page', 'https://www.xicidaili.com/nn/13.html')
2020-05-15 14:27:42,129 - xici_ip_model.py[line:47] - ERROR: stack is empty
2020-05-15 14:27:42,129 - xici_ip_model.py[line:31] - INFO: ('start get 1 page', 'https://www.xicidaili.com/nn/14.html')
2020-05-15 14:27:42,389 - xici_ip_model.py[line:47] - ERROR: stack is empty
2020-05-15 14:27:42,392 - xici_ip_model.py[line:31] - INFO: ('start get 1 page', 'https://www.xicidaili.com/nn/15.html')
2020-05-15 14:27:42,647 - xici_ip_model.py[line:47] - ERROR: stack is empty
2020-05-15 14:27:42,647 - xici_ip_model.py[line:31] - INFO: ('start get 1 page', 'https://www.xicidaili.com/nn/16.html')
2020-05-15 14:27:42,899 - xici_ip_model.py[line:47] - ERROR: stack is empty
2020-05-15 14:27:42,899 - xici_ip_model.py[line:31] - INFO: ('start get 1 page', 'https://www.xicidaili.com/nn/17.html')
2020-05-15 14:27:43,170 - xici_ip_model.py[line:47] - ERROR: stack is empty
2020-05-15 14:27:43,171 - xici_ip_model.py[line:31] - INFO: ('start get 1 page', 'https://www.xicidaili.com/nn/18.html')
2020-05-15 14:27:43,469 - xici_ip_model.py[line:47] - ERROR: stack is empty
2020-05-15 14:27:43,470 - xici_ip_model.py[line:31] - INFO: ('start get 1 page', 'https://www.xicidaili.com/nn/19.html')
2020-05-15 14:27:43,734 - xici_ip_model.py[line:47] - ERROR: stack is empty
2020-05-15 14:27:43,738 - xici_ip_model.py[line:31] - INFO: ('start get 1 page', 'https://www.xicidaili.com/nn/20.html')
2020-05-15 14:27:43,996 - xici_ip_model.py[line:47] - ERROR: stack is empty
2020-05-15 14:27:43,996 - xici_ip_model.py[line:31] - INFO: ('start get 1 page', 'https://www.xicidaili.com/nn/21.html')
2020-05-15 14:27:44,268 - xici_ip_model.py[line:47] - ERROR: stack is empty
2020-05-15 14:27:44,269 - xici_ip_model.py[line:31] - INFO: ('start get 1 page', 'https://www.xicidaili.com/nn/22.html')
2020-05-15 14:27:44,547 - xici_ip_model.py[line:47] - ERROR: stack is empty
2020-05-15 14:27:44,548 - xici_ip_model.py[line:31] - INFO: ('start get 1 page', 'https://www.xicidaili.com/nn/23.html')
2020-05-15 14:27:44,829 - xici_ip_model.py[line:47] - ERROR: stack is empty
2020-05-15 14:27:44,830 - xici_ip_model.py[line:31] - INFO: ('start get 1 page', 'https://www.xicidaili.com/nn/24.html')
2020-05-15 14:27:45,110 - xici_ip_model.py[line:47] - ERROR: stack is empty
2020-05-15 14:27:45,111 - xici_ip_model.py[line:31] - INFO: ('start get 1 page', 'https://www.xicidaili.com/nn/25.html')
2020-05-15 14:27:45,368 - xici_ip_model.py[line:47] - ERROR: stack is empty
2020-05-15 14:27:45,369 - xici_ip_model.py[line:31] - INFO: ('start get 1 page', 'https://www.xicidaili.com/nn/26.html')
2020-05-15 14:27:45,621 - xici_ip_model.py[line:47] - ERROR: stack is empty
2020-05-15 14:27:45,621 - xici_ip_model.py[line:31] - INFO: ('start get 1 page', 'https://www.xicidaili.com/nn/27.html')
2020-05-15 14:27:45,901 - xici_ip_model.py[line:47] - ERROR: stack is empty
2020-05-15 14:27:45,902 - xici_ip_model.py[line:31] - INFO: ('start get 1 page', 'https://www.xicidaili.com/nn/28.html')
2020-05-15 14:28:01,126 - xici_ip_model.py[line:31] - INFO: ('start get 1 page', 'https://www.xicidaili.com/nn/1.html')
2020-05-15 14:28:01,406 - xici_ip_model.py[line:47] - ERROR: stack is empty
2020-05-15 14:28:01,406 - xici_ip_model.py[line:31] - INFO: ('start get 1 page', 'https://www.xicidaili.com/nn/2.html')
2020-05-15 14:28:01,686 - xici_ip_model.py[line:47] - ERROR: stack is empty
2020-05-15 14:28:01,687 - xici_ip_model.py[line:31] - INFO: ('start get 1 page', 'https://www.xicidaili.com/nn/3.html')
2020-05-15 14:28:01,942 - xici_ip_model.py[line:47] - ERROR: stack is empty
2020-05-15 14:28:01,944 - xici_ip_model.py[line:31] - INFO: ('start get 1 page', 'https://www.xicidaili.com/nn/4.html')
2020-05-15 14:28:02,202 - xici_ip_model.py[line:47] - ERROR: stack is empty
2020-05-15 14:28:02,204 - xici_ip_model.py[line:31] - INFO: ('start get 1 page', 'https://www.xicidaili.com/nn/5.html')
2020-05-15 14:28:02,464 - xici_ip_model.py[line:47] - ERROR: stack is empty
2020-05-15 14:28:02,465 - xici_ip_model.py[line:31] - INFO: ('start get 1 page', 'https://www.xicidaili.com/nn/6.html')
2020-05-15 14:28:02,725 - xici_ip_model.py[line:47] - ERROR: stack is empty
2020-05-15 14:28:02,726 - xici_ip_model.py[line:31] - INFO: ('start get 1 page', 'https://www.xicidaili.com/nn/7.html')
2020-05-15 14:28:03,001 - xici_ip_model.py[line:47] - ERROR: stack is empty
2020-05-15 14:28:03,002 - xici_ip_model.py[line:31] - INFO: ('start get 1 page', 'https://www.xicidaili.com/nn/8.html')
2020-05-15 14:28:03,265 - xici_ip_model.py[line:47] - ERROR: stack is empty
2020-05-15 14:28:03,268 - xici_ip_model.py[line:31] - INFO: ('start get 1 page', 'https://www.xicidaili.com/nn/9.html')
2020-05-15 14:28:03,541 - xici_ip_model.py[line:47] - ERROR: stack is empty
2020-05-15 14:28:03,541 - xici_ip_model.py[line:31] - INFO: ('start get 1 page', 'https://www.xicidaili.com/nn/10.html')
2020-05-15 14:28:03,821 - xici_ip_model.py[line:47] - ERROR: stack is empty
2020-05-15 14:28:03,821 - xici_ip_model.py[line:31] - INFO: ('start get 1 page', 'https://www.xicidaili.com/nn/11.html')
2020-05-15 14:28:04,080 - xici_ip_model.py[line:47] - ERROR: stack is empty
2020-05-15 14:28:04,080 - xici_ip_model.py[line:31] - INFO: ('start get 1 page', 'https://www.xicidaili.com/nn/12.html')
2020-05-15 14:28:04,372 - xici_ip_model.py[line:47] - ERROR: stack is empty
2020-05-15 14:28:04,375 - xici_ip_model.py[line:31] - INFO: ('start get 1 page', 'https://www.xicidaili.com/nn/13.html')
2020-05-15 14:28:04,630 - xici_ip_model.py[line:47] - ERROR: stack is empty
2020-05-15 14:28:04,631 - xici_ip_model.py[line:31] - INFO: ('start get 1 page', 'https://www.xicidaili.com/nn/14.html')
2020-05-15 14:44:17,425 - xici_ip_model.py[line:31] - INFO: ('start get 1 page', 'https://www.xicidaili.com/nn/1.html')
2020-05-15 14:44:17,693 - xici_ip_model.py[line:47] - ERROR: set is empty
2020-05-15 14:44:17,694 - xici_ip_model.py[line:31] - INFO: ('start get 1 page', 'https://www.xicidaili.com/nn/2.html')
2020-05-15 14:44:17,946 - xici_ip_model.py[line:47] - ERROR: set is empty
2020-05-15 14:44:17,946 - xici_ip_model.py[line:31] - INFO: ('start get 1 page', 'https://www.xicidaili.com/nn/3.html')
2020-05-15 14:44:18,247 - xici_ip_model.py[line:47] - ERROR: set is empty
2020-05-15 14:44:18,247 - xici_ip_model.py[line:31] - INFO: ('start get 1 page', 'https://www.xicidaili.com/nn/4.html')
2020-05-15 14:44:18,501 - xici_ip_model.py[line:47] - ERROR: set is empty
2020-05-15 14:44:18,502 - xici_ip_model.py[line:31] - INFO: ('start get 1 page', 'https://www.xicidaili.com/nn/5.html')
2020-05-15 14:44:18,780 - xici_ip_model.py[line:47] - ERROR: set is empty
2020-05-15 14:44:18,780 - xici_ip_model.py[line:31] - INFO: ('start get 1 page', 'https://www.xicidaili.com/nn/6.html')
2020-05-15 14:44:19,034 - xici_ip_model.py[line:47] - ERROR: set is empty
2020-05-15 14:44:19,035 - xici_ip_model.py[line:31] - INFO: ('start get 1 page', 'https://www.xicidaili.com/nn/7.html')
2020-05-15 14:44:19,320 - xici_ip_model.py[line:47] - ERROR: set is empty
2020-05-15 14:44:19,321 - xici_ip_model.py[line:31] - INFO: ('start get 1 page', 'https://www.xicidaili.com/nn/8.html')
2020-05-15 14:44:19,581 - xici_ip_model.py[line:47] - ERROR: set is empty
2020-05-15 14:44:19,581 - xici_ip_model.py[line:31] - INFO: ('start get 1 page', 'https://www.xicidaili.com/nn/9.html')
2020-05-15 14:44:19,869 - xici_ip_model.py[line:47] - ERROR: set is empty
2020-05-15 14:44:19,871 - xici_ip_model.py[line:31] - INFO: ('start get 1 page', 'https://www.xicidaili.com/nn/10.html')
2020-05-15 14:44:20,168 - xici_ip_model.py[line:47] - ERROR: set is empty
2020-05-15 14:44:20,171 - xici_ip_model.py[line:31] - INFO: ('start get 1 page', 'https://www.xicidaili.com/nn/11.html')
2020-05-15 14:44:20,426 - xici_ip_model.py[line:47] - ERROR: set is empty
2020-05-15 14:44:20,427 - xici_ip_model.py[line:31] - INFO: ('start get 1 page', 'https://www.xicidaili.com/nn/12.html')
2020-05-15 14:44:20,706 - xici_ip_model.py[line:47] - ERROR: set is empty
2020-05-15 14:44:20,707 - xici_ip_model.py[line:31] - INFO: ('start get 1 page', 'https://www.xicidaili.com/nn/13.html')
2020-05-15 15:02:00,771 - ip_verify.py[line:67] - INFO: start connection to 115.196.195.120:8060
2020-05-15 15:02:00,776 - ip_verify.py[line:67] - INFO: start connection to 117.88.177.32:3000
2020-05-15 15:02:00,779 - ip_verify.py[line:67] - INFO: start connection to 101.132.190.101:80
2020-05-15 15:02:00,781 - ip_verify.py[line:67] - INFO: start connection to 117.88.176.170:3000
2020-05-15 15:02:00,785 - ip_verify.py[line:67] - INFO: start connection to 117.88.176.42:3000
2020-05-15 15:02:00,787 - ip_verify.py[line:67] - INFO: start connection to 117.88.176.134:3000
2020-05-15 15:02:00,789 - ip_verify.py[line:94] - INFO: ('线程池容量', 10)
2020-05-15 15:02:00,789 - ip_verify.py[line:67] - INFO: start connection to 222.95.144.87:3000
2020-05-15 15:02:00,791 - ip_verify.py[line:95] - INFO: ('堆栈量', 0)
2020-05-15 15:02:00,792 - ip_verify.py[line:67] - INFO: start connection to 27.184.123.176:8118
2020-05-15 15:02:00,796 - ip_verify.py[line:67] - INFO: start connection to 121.237.148.193:3000
2020-05-15 15:02:00,799 - ip_verify.py[line:67] - INFO: start connection to 219.143.207.45:800
2020-05-15 15:02:00,801 - ip_verify.py[line:67] - INFO: start connection to 106.15.126.137:8080
2020-05-15 15:02:01,578 - ip_verify.py[line:72] - INFO: {
  "args": {}, 
  "headers": {
    "Accept": "*/*", 
    "Accept-Encoding": "gzip, deflate", 
    "Host": "httpbin.org", 
    "User-Agent": "python-requests/2.20.0", 
    "X-Amzn-Trace-Id": "Root=1-5ebe3e69-bf4ee26e7d8db42f47a4d709"
  }, 
  "origin": "101.132.190.101", 
  "url": "http://httpbin.org/get"
}

2020-05-15 15:02:01,579 - redis_memory.py[line:65] - INFO: ('set row', '101.132.190.101:80')
2020-05-15 15:02:01,579 - ip_verify.py[line:82] - INFO: ('en stack 1 url', '101.132.190.101:80')
2020-05-15 15:02:01,892 - ip_verify.py[line:70] - INFO: 连接错误HTTPConnectionPool(host='117.88.177.32', port=3000): Max retries exceeded with url: http://httpbin.org/get (Caused by ProxyError('Cannot connect to proxy.', NewConnectionError('<urllib3.connection.HTTPConnection object at 0x000002BEA1DAA208>: Failed to establish a new connection: [WinError 10061] 由于目标计算机积极拒绝，无法连接。')))
2020-05-15 15:02:01,893 - ip_verify.py[line:84] - INFO: ('invalid url', '117.88.177.32:3000')
2020-05-15 15:02:01,893 - ip_verify.py[line:70] - INFO: 连接错误HTTPConnectionPool(host='115.196.195.120', port=8060): Max retries exceeded with url: http://httpbin.org/get (Caused by ProxyError('Cannot connect to proxy.', NewConnectionError('<urllib3.connection.HTTPConnection object at 0x000002BEA1D8E708>: Failed to establish a new connection: [WinError 10061] 由于目标计算机积极拒绝，无法连接。')))
2020-05-15 15:02:01,893 - ip_verify.py[line:84] - INFO: ('invalid url', '115.196.195.120:8060')
2020-05-15 15:02:01,903 - ip_verify.py[line:70] - INFO: 连接错误HTTPConnectionPool(host='117.88.176.42', port=3000): Max retries exceeded with url: http://httpbin.org/get (Caused by ProxyError('Cannot connect to proxy.', NewConnectionError('<urllib3.connection.HTTPConnection object at 0x000002BEA1DC6188>: Failed to establish a new connection: [WinError 10061] 由于目标计算机积极拒绝，无法连接。')))
2020-05-15 15:02:01,903 - ip_verify.py[line:84] - INFO: ('invalid url', '117.88.176.42:3000')
2020-05-15 15:02:08,784 - ip_verify.py[line:70] - INFO: 连接错误HTTPConnectionPool(host='117.88.176.170', port=3000): Max retries exceeded with url: http://httpbin.org/get (Caused by ConnectTimeoutError(<urllib3.connection.HTTPConnection object at 0x000002BEA1DBB548>, 'Connection to 117.88.176.170 timed out. (connect timeout=8)'))
2020-05-15 15:02:08,785 - ip_verify.py[line:84] - INFO: ('invalid url', '117.88.176.170:3000')
2020-05-15 15:02:08,790 - ip_verify.py[line:70] - INFO: 连接错误HTTPConnectionPool(host='117.88.176.134', port=3000): Max retries exceeded with url: http://httpbin.org/get (Caused by ConnectTimeoutError(<urllib3.connection.HTTPConnection object at 0x000002BEA1DCD9C8>, 'Connection to 117.88.176.134 timed out. (connect timeout=8)'))
2020-05-15 15:02:08,791 - ip_verify.py[line:84] - INFO: ('invalid url', '117.88.176.134:3000')
2020-05-15 15:02:08,792 - ip_verify.py[line:70] - INFO: 连接错误HTTPConnectionPool(host='222.95.144.87', port=3000): Max retries exceeded with url: http://httpbin.org/get (Caused by ConnectTimeoutError(<urllib3.connection.HTTPConnection object at 0x000002BEA1DD72C8>, 'Connection to 222.95.144.87 timed out. (connect timeout=8)'))
2020-05-15 15:02:08,793 - ip_verify.py[line:84] - INFO: ('invalid url', '222.95.144.87:3000')
2020-05-15 15:02:08,794 - ip_verify.py[line:70] - INFO: 连接错误HTTPConnectionPool(host='27.184.123.176', port=8118): Max retries exceeded with url: http://httpbin.org/get (Caused by ConnectTimeoutError(<urllib3.connection.HTTPConnection object at 0x000002BEA1DDA9C8>, 'Connection to 27.184.123.176 timed out. (connect timeout=8)'))
2020-05-15 15:02:08,795 - ip_verify.py[line:84] - INFO: ('invalid url', '27.184.123.176:8118')
2020-05-15 15:02:08,797 - ip_verify.py[line:70] - INFO: 连接错误HTTPConnectionPool(host='121.237.148.193', port=3000): Max retries exceeded with url: http://httpbin.org/get (Caused by ConnectTimeoutError(<urllib3.connection.HTTPConnection object at 0x000002BEA1DE9188>, 'Connection to 121.237.148.193 timed out. (connect timeout=8)'))
2020-05-15 15:02:08,798 - ip_verify.py[line:84] - INFO: ('invalid url', '121.237.148.193:3000')
2020-05-15 15:02:08,803 - ip_verify.py[line:70] - INFO: 连接错误HTTPConnectionPool(host='106.15.126.137', port=8080): Max retries exceeded with url: http://httpbin.org/get (Caused by ConnectTimeoutError(<urllib3.connection.HTTPConnection object at 0x000002BEA1DF9088>, 'Connection to 106.15.126.137 timed out. (connect timeout=8)'))
2020-05-15 15:02:08,804 - ip_verify.py[line:84] - INFO: ('invalid url', '106.15.126.137:8080')
2020-05-15 15:02:10,796 - ip_verify.py[line:67] - INFO: start connection to 182.96.158.55:8118
2020-05-15 15:02:10,799 - ip_verify.py[line:67] - INFO: start connection to 114.104.17.178:10098
2020-05-15 15:02:10,801 - ip_verify.py[line:67] - INFO: start connection to 115.204.198.148:8118
2020-05-15 15:02:10,804 - ip_verify.py[line:67] - INFO: start connection to 121.8.146.99:8060
2020-05-15 15:02:10,807 - ip_verify.py[line:67] - INFO: start connection to 117.88.177.93:3000
2020-05-15 15:02:10,809 - ip_verify.py[line:67] - INFO: start connection to 111.76.168.201:8118
2020-05-15 15:02:10,811 - ip_verify.py[line:67] - INFO: start connection to 221.182.89.234:63000
2020-05-15 15:02:10,813 - ip_verify.py[line:94] - INFO: ('线程池容量', 10)
2020-05-15 15:02:10,814 - ip_verify.py[line:95] - INFO: ('堆栈量', 1)
2020-05-15 15:02:10,815 - ip_verify.py[line:67] - INFO: start connection to 117.88.176.229:3000
2020-05-15 15:02:10,816 - ip_verify.py[line:67] - INFO: start connection to 60.184.196.213:8888
2020-05-15 15:02:10,819 - ip_verify.py[line:67] - INFO: start connection to 183.166.171.252:61234
2020-05-15 15:02:10,839 - ip_verify.py[line:70] - INFO: 连接错误HTTPConnectionPool(host='221.182.89.234', port=63000): Max retries exceeded with url: http://httpbin.org/get (Caused by ProxyError('Cannot connect to proxy.', RemoteDisconnected('Remote end closed connection without response')))
2020-05-15 15:02:10,839 - ip_verify.py[line:84] - INFO: ('invalid url', '221.182.89.234:63000')
2020-05-15 15:02:11,845 - ip_verify.py[line:70] - INFO: 连接错误HTTPConnectionPool(host='219.143.207.45', port=800): Read timed out. (read timeout=8)
2020-05-15 15:02:11,845 - ip_verify.py[line:84] - INFO: ('invalid url', '219.143.207.45:800')
2020-05-15 15:02:11,896 - ip_verify.py[line:70] - INFO: 连接错误HTTPConnectionPool(host='182.96.158.55', port=8118): Max retries exceeded with url: http://httpbin.org/get (Caused by ProxyError('Cannot connect to proxy.', NewConnectionError('<urllib3.connection.HTTPConnection object at 0x000002BEA1DAAB08>: Failed to establish a new connection: [WinError 10061] 由于目标计算机积极拒绝，无法连接。')))
2020-05-15 15:02:11,897 - ip_verify.py[line:84] - INFO: ('invalid url', '182.96.158.55:8118')
2020-05-15 15:02:11,924 - ip_verify.py[line:70] - INFO: 连接错误HTTPConnectionPool(host='115.204.198.148', port=8118): Max retries exceeded with url: http://httpbin.org/get (Caused by ProxyError('Cannot connect to proxy.', NewConnectionError('<urllib3.connection.HTTPConnection object at 0x000002BEA1E11248>: Failed to establish a new connection: [WinError 10061] 由于目标计算机积极拒绝，无法连接。')))
2020-05-15 15:02:11,925 - ip_verify.py[line:84] - INFO: ('invalid url', '115.204.198.148:8118')
2020-05-15 15:02:11,926 - ip_verify.py[line:70] - INFO: 连接错误HTTPConnectionPool(host='111.76.168.201', port=8118): Max retries exceeded with url: http://httpbin.org/get (Caused by ProxyError('Cannot connect to proxy.', NewConnectionError('<urllib3.connection.HTTPConnection object at 0x000002BEA1DCDC88>: Failed to establish a new connection: [WinError 10061] 由于目标计算机积极拒绝，无法连接。')))
2020-05-15 15:02:11,926 - ip_verify.py[line:84] - INFO: ('invalid url', '111.76.168.201:8118')
2020-05-15 15:02:11,942 - ip_verify.py[line:70] - INFO: 连接错误HTTPConnectionPool(host='117.88.176.229', port=3000): Max retries exceeded with url: http://httpbin.org/get (Caused by ProxyError('Cannot connect to proxy.', NewConnectionError('<urllib3.connection.HTTPConnection object at 0x000002BEA1DC61C8>: Failed to establish a new connection: [WinError 10061] 由于目标计算机积极拒绝，无法连接。')))
2020-05-15 15:02:11,943 - ip_verify.py[line:84] - INFO: ('invalid url', '117.88.176.229:3000')
2020-05-15 15:02:11,953 - ip_verify.py[line:70] - INFO: 连接错误HTTPConnectionPool(host='183.166.171.252', port=61234): Max retries exceeded with url: http://httpbin.org/get (Caused by ProxyError('Cannot connect to proxy.', NewConnectionError('<urllib3.connection.HTTPConnection object at 0x000002BEA1DB3388>: Failed to establish a new connection: [WinError 10061] 由于目标计算机积极拒绝，无法连接。')))
2020-05-15 15:02:11,954 - ip_verify.py[line:84] - INFO: ('invalid url', '183.166.171.252:61234')
2020-05-15 15:02:11,957 - ip_verify.py[line:70] - INFO: 连接错误HTTPConnectionPool(host='60.184.196.213', port=8888): Max retries exceeded with url: http://httpbin.org/get (Caused by ProxyError('Cannot connect to proxy.', NewConnectionError('<urllib3.connection.HTTPConnection object at 0x000002BEA1DA5DC8>: Failed to establish a new connection: [WinError 10061] 由于目标计算机积极拒绝，无法连接。')))
2020-05-15 15:02:11,958 - ip_verify.py[line:84] - INFO: ('invalid url', '60.184.196.213:8888')
2020-05-15 15:02:18,802 - ip_verify.py[line:70] - INFO: 连接错误HTTPConnectionPool(host='114.104.17.178', port=10098): Max retries exceeded with url: http://httpbin.org/get (Caused by ConnectTimeoutError(<urllib3.connection.HTTPConnection object at 0x000002BEA1DB1E88>, 'Connection to 114.104.17.178 timed out. (connect timeout=8)'))
2020-05-15 15:02:18,802 - ip_verify.py[line:84] - INFO: ('invalid url', '114.104.17.178:10098')
2020-05-15 15:02:18,806 - ip_verify.py[line:70] - INFO: 连接错误HTTPConnectionPool(host='121.8.146.99', port=8060): Max retries exceeded with url: http://httpbin.org/get (Caused by ConnectTimeoutError(<urllib3.connection.HTTPConnection object at 0x000002BEA1DDA6C8>, 'Connection to 121.8.146.99 timed out. (connect timeout=8)'))
2020-05-15 15:02:18,806 - ip_verify.py[line:84] - INFO: ('invalid url', '121.8.146.99:8060')
2020-05-15 15:02:18,809 - ip_verify.py[line:70] - INFO: 连接错误HTTPConnectionPool(host='117.88.177.93', port=3000): Max retries exceeded with url: http://httpbin.org/get (Caused by ConnectTimeoutError(<urllib3.connection.HTTPConnection object at 0x000002BEA1DD7988>, 'Connection to 117.88.177.93 timed out. (connect timeout=8)'))
2020-05-15 15:02:18,809 - ip_verify.py[line:84] - INFO: ('invalid url', '117.88.177.93:3000')
2020-05-15 15:02:20,819 - ip_verify.py[line:67] - INFO: start connection to 125.40.11.183:8118
2020-05-15 15:02:20,821 - ip_verify.py[line:67] - INFO: start connection to 175.148.77.47:1133
2020-05-15 15:02:20,823 - ip_verify.py[line:67] - INFO: start connection to 222.95.144.68:3000
2020-05-15 15:02:20,825 - ip_verify.py[line:67] - INFO: start connection to 175.148.78.181:1133
2020-05-15 15:02:20,829 - ip_verify.py[line:67] - INFO: start connection to 117.88.4.91:3000
2020-05-15 15:02:20,832 - ip_verify.py[line:67] - INFO: start connection to 121.237.148.211:3000
2020-05-15 15:02:20,834 - ip_verify.py[line:67] - INFO: start connection to 222.95.144.189:3000
2020-05-15 15:02:20,837 - ip_verify.py[line:67] - INFO: start connection to 121.237.148.155:3000
2020-05-15 15:02:20,838 - ip_verify.py[line:94] - INFO: ('线程池容量', 10)
2020-05-15 15:02:20,839 - ip_verify.py[line:67] - INFO: start connection to 117.88.5.197:3000
2020-05-15 15:02:20,840 - ip_verify.py[line:95] - INFO: ('堆栈量', 1)
2020-05-15 15:02:20,842 - ip_verify.py[line:67] - INFO: start connection to 115.221.240.171:9999
2020-05-15 15:02:20,845 - ip_verify.py[line:67] - INFO: start connection to 117.88.5.241:3000
2020-05-15 15:02:21,919 - ip_verify.py[line:70] - INFO: 连接错误HTTPConnectionPool(host='125.40.11.183', port=8118): Max retries exceeded with url: http://httpbin.org/get (Caused by ProxyError('Cannot connect to proxy.', NewConnectionError('<urllib3.connection.HTTPConnection object at 0x000002BEA1DE93C8>: Failed to establish a new connection: [WinError 10061] 由于目标计算机积极拒绝，无法连接。')))
2020-05-15 15:02:21,919 - ip_verify.py[line:84] - INFO: ('invalid url', '125.40.11.183:8118')
2020-05-15 15:02:21,959 - ip_verify.py[line:70] - INFO: 连接错误HTTPConnectionPool(host='222.95.144.68', port=3000): Max retries exceeded with url: http://httpbin.org/get (Caused by ProxyError('Cannot connect to proxy.', NewConnectionError('<urllib3.connection.HTTPConnection object at 0x000002BEA1E18608>: Failed to establish a new connection: [WinError 10061] 由于目标计算机积极拒绝，无法连接。')))
2020-05-15 15:02:21,959 - ip_verify.py[line:84] - INFO: ('invalid url', '222.95.144.68:3000')
2020-05-15 15:02:21,967 - ip_verify.py[line:70] - INFO: 连接错误HTTPConnectionPool(host='117.88.5.197', port=3000): Max retries exceeded with url: http://httpbin.org/get (Caused by ProxyError('Cannot connect to proxy.', NewConnectionError('<urllib3.connection.HTTPConnection object at 0x000002BEA1DB1948>: Failed to establish a new connection: [WinError 10061] 由于目标计算机积极拒绝，无法连接。')))
2020-05-15 15:02:21,967 - ip_verify.py[line:84] - INFO: ('invalid url', '117.88.5.197:3000')
2020-05-15 15:02:21,988 - ip_verify.py[line:70] - INFO: 连接错误HTTPConnectionPool(host='121.237.148.155', port=3000): Max retries exceeded with url: http://httpbin.org/get (Caused by ProxyError('Cannot connect to proxy.', NewConnectionError('<urllib3.connection.HTTPConnection object at 0x000002BEA1DF05C8>: Failed to establish a new connection: [WinError 10061] 由于目标计算机积极拒绝，无法连接。')))
2020-05-15 15:02:21,988 - ip_verify.py[line:84] - INFO: ('invalid url', '121.237.148.155:3000')
2020-05-15 15:02:28,823 - ip_verify.py[line:70] - INFO: 连接错误HTTPConnectionPool(host='175.148.77.47', port=1133): Max retries exceeded with url: http://httpbin.org/get (Caused by ConnectTimeoutError(<urllib3.connection.HTTPConnection object at 0x000002BEA1DF0308>, 'Connection to 175.148.77.47 timed out. (connect timeout=8)'))
2020-05-15 15:02:28,824 - ip_verify.py[line:84] - INFO: ('invalid url', '175.148.77.47:1133')
2020-05-15 15:02:28,827 - ip_verify.py[line:70] - INFO: 连接错误HTTPConnectionPool(host='175.148.78.181', port=1133): Max retries exceeded with url: http://httpbin.org/get (Caused by ConnectTimeoutError(<urllib3.connection.HTTPConnection object at 0x000002BEA1E1CCC8>, 'Connection to 175.148.78.181 timed out. (connect timeout=8)'))
2020-05-15 15:02:28,828 - ip_verify.py[line:84] - INFO: ('invalid url', '175.148.78.181:1133')
2020-05-15 15:02:28,830 - ip_verify.py[line:70] - INFO: 连接错误HTTPConnectionPool(host='117.88.4.91', port=3000): Max retries exceeded with url: http://httpbin.org/get (Caused by ConnectTimeoutError(<urllib3.connection.HTTPConnection object at 0x000002BEA1DF9748>, 'Connection to 117.88.4.91 timed out. (connect timeout=8)'))
2020-05-15 15:02:28,831 - ip_verify.py[line:84] - INFO: ('invalid url', '117.88.4.91:3000')
2020-05-15 15:02:28,834 - ip_verify.py[line:70] - INFO: 连接错误HTTPConnectionPool(host='121.237.148.211', port=3000): Max retries exceeded with url: http://httpbin.org/get (Caused by ConnectTimeoutError(<urllib3.connection.HTTPConnection object at 0x000002BEA1DDA188>, 'Connection to 121.237.148.211 timed out. (connect timeout=8)'))
2020-05-15 15:02:28,835 - ip_verify.py[line:84] - INFO: ('invalid url', '121.237.148.211:3000')
2020-05-15 15:02:28,836 - ip_verify.py[line:70] - INFO: 连接错误HTTPConnectionPool(host='222.95.144.189', port=3000): Max retries exceeded with url: http://httpbin.org/get (Caused by ConnectTimeoutError(<urllib3.connection.HTTPConnection object at 0x000002BEA1DD7908>, 'Connection to 222.95.144.189 timed out. (connect timeout=8)'))
2020-05-15 15:02:28,837 - ip_verify.py[line:84] - INFO: ('invalid url', '222.95.144.189:3000')
2020-05-15 15:02:28,844 - ip_verify.py[line:70] - INFO: 连接错误HTTPConnectionPool(host='115.221.240.171', port=9999): Max retries exceeded with url: http://httpbin.org/get (Caused by ConnectTimeoutError(<urllib3.connection.HTTPConnection object at 0x000002BEA1DBB388>, 'Connection to 115.221.240.171 timed out. (connect timeout=8)'))
2020-05-15 15:02:28,845 - ip_verify.py[line:84] - INFO: ('invalid url', '115.221.240.171:9999')
2020-05-15 15:02:28,846 - ip_verify.py[line:70] - INFO: 连接错误HTTPConnectionPool(host='117.88.5.241', port=3000): Max retries exceeded with url: http://httpbin.org/get (Caused by ConnectTimeoutError(<urllib3.connection.HTTPConnection object at 0x000002BEA1DC6888>, 'Connection to 117.88.5.241 timed out. (connect timeout=8)'))
2020-05-15 15:02:28,847 - ip_verify.py[line:84] - INFO: ('invalid url', '117.88.5.241:3000')
2020-05-15 15:02:30,845 - ip_verify.py[line:67] - INFO: start connection to 117.88.177.86:3000
2020-05-15 15:02:30,848 - ip_verify.py[line:67] - INFO: start connection to 171.35.163.6:9999
2020-05-15 15:02:30,851 - ip_verify.py[line:67] - INFO: start connection to 114.99.0.211:808
2020-05-15 15:02:30,853 - ip_verify.py[line:67] - INFO: start connection to 113.195.171.75:9999
2020-05-15 15:02:30,855 - ip_verify.py[line:67] - INFO: start connection to 222.95.144.121:3000
2020-05-15 15:02:30,858 - ip_verify.py[line:67] - INFO: start connection to 117.88.5.116:3000
2020-05-15 15:02:30,861 - ip_verify.py[line:67] - INFO: start connection to 118.24.118.207:808
2020-05-15 15:02:30,862 - ip_verify.py[line:94] - INFO: ('线程池容量', 10)
2020-05-15 15:02:30,863 - ip_verify.py[line:95] - INFO: ('堆栈量', 1)
2020-05-15 15:02:30,863 - ip_verify.py[line:67] - INFO: start connection to 112.192.34.47:1133
2020-05-15 15:02:30,866 - ip_verify.py[line:67] - INFO: start connection to 171.35.166.86:9999
2020-05-15 15:02:30,867 - ip_verify.py[line:67] - INFO: start connection to 110.243.8.26:9999
2020-05-15 15:02:30,870 - ip_verify.py[line:67] - INFO: start connection to 60.217.129.63:8060
2020-05-15 15:02:30,877 - ip_verify.py[line:72] - INFO: <html><head><meta http-equiv="Content-Type" content="text/html; charset=utf-8" /></head><body><h1>Unauthorized ...</h1>
<h2>IP Address: 171.212.254.110:29441<br>
MAC Address: <br>
Server Time: 2020-05-15 15:02:29<br>
Auth Result: </h2></body></html>
2020-05-15 15:02:30,878 - ip_verify.py[line:84] - INFO: ('invalid url', '118.24.118.207:808')
2020-05-15 15:02:31,976 - ip_verify.py[line:70] - INFO: 连接错误HTTPConnectionPool(host='222.95.144.121', port=3000): Max retries exceeded with url: http://httpbin.org/get (Caused by ProxyError('Cannot connect to proxy.', NewConnectionError('<urllib3.connection.HTTPConnection object at 0x000002BEA1D78B48>: Failed to establish a new connection: [WinError 10061] 由于目标计算机积极拒绝，无法连接。')))
2020-05-15 15:02:31,977 - ip_verify.py[line:84] - INFO: ('invalid url', '222.95.144.121:3000')
2020-05-15 15:02:31,991 - ip_verify.py[line:70] - INFO: 连接错误HTTPConnectionPool(host='117.88.5.116', port=3000): Max retries exceeded with url: http://httpbin.org/get (Caused by ProxyError('Cannot connect to proxy.', NewConnectionError('<urllib3.connection.HTTPConnection object at 0x000002BEA1DE37C8>: Failed to establish a new connection: [WinError 10061] 由于目标计算机积极拒绝，无法连接。')))
2020-05-15 15:02:31,992 - ip_verify.py[line:84] - INFO: ('invalid url', '117.88.5.116:3000')
2020-05-15 15:02:32,030 - ip_verify.py[line:70] - INFO: 连接错误HTTPConnectionPool(host='171.35.166.86', port=9999): Max retries exceeded with url: http://httpbin.org/get (Caused by ProxyError('Cannot connect to proxy.', NewConnectionError('<urllib3.connection.HTTPConnection object at 0x000002BEA1E18AC8>: Failed to establish a new connection: [WinError 10061] 由于目标计算机积极拒绝，无法连接。')))
2020-05-15 15:02:32,031 - ip_verify.py[line:84] - INFO: ('invalid url', '171.35.166.86:9999')
2020-05-15 15:02:38,847 - ip_verify.py[line:70] - INFO: 连接错误HTTPConnectionPool(host='117.88.177.86', port=3000): Max retries exceeded with url: http://httpbin.org/get (Caused by ConnectTimeoutError(<urllib3.connection.HTTPConnection object at 0x000002BEA1DC2A08>, 'Connection to 117.88.177.86 timed out. (connect timeout=8)'))
2020-05-15 15:02:38,848 - ip_verify.py[line:84] - INFO: ('invalid url', '117.88.177.86:3000')
2020-05-15 15:02:38,850 - ip_verify.py[line:70] - INFO: 连接错误HTTPConnectionPool(host='171.35.163.6', port=9999): Max retries exceeded with url: http://httpbin.org/get (Caused by ConnectTimeoutError(<urllib3.connection.HTTPConnection object at 0x000002BEA1DB3248>, 'Connection to 171.35.163.6 timed out. (connect timeout=8)'))
2020-05-15 15:02:38,851 - ip_verify.py[line:84] - INFO: ('invalid url', '171.35.163.6:9999')
2020-05-15 15:02:38,852 - ip_verify.py[line:70] - INFO: 连接错误HTTPConnectionPool(host='114.99.0.211', port=808): Max retries exceeded with url: http://httpbin.org/get (Caused by ConnectTimeoutError(<urllib3.connection.HTTPConnection object at 0x000002BEA1D8E748>, 'Connection to 114.99.0.211 timed out. (connect timeout=8)'))
2020-05-15 15:02:38,853 - ip_verify.py[line:84] - INFO: ('invalid url', '114.99.0.211:808')
2020-05-15 15:02:38,857 - ip_verify.py[line:70] - INFO: 连接错误HTTPConnectionPool(host='113.195.171.75', port=9999): Max retries exceeded with url: http://httpbin.org/get (Caused by ConnectTimeoutError(<urllib3.connection.HTTPConnection object at 0x000002BEA1E21D48>, 'Connection to 113.195.171.75 timed out. (connect timeout=8)'))
2020-05-15 15:02:38,858 - ip_verify.py[line:84] - INFO: ('invalid url', '113.195.171.75:9999')
2020-05-15 15:02:38,865 - ip_verify.py[line:70] - INFO: 连接错误HTTPConnectionPool(host='112.192.34.47', port=1133): Max retries exceeded with url: http://httpbin.org/get (Caused by ConnectTimeoutError(<urllib3.connection.HTTPConnection object at 0x000002BEA1E11EC8>, 'Connection to 112.192.34.47 timed out. (connect timeout=8)'))
2020-05-15 15:02:38,866 - ip_verify.py[line:84] - INFO: ('invalid url', '112.192.34.47:1133')
2020-05-15 15:02:38,869 - ip_verify.py[line:70] - INFO: 连接错误HTTPConnectionPool(host='110.243.8.26', port=9999): Max retries exceeded with url: http://httpbin.org/get (Caused by ConnectTimeoutError(<urllib3.connection.HTTPConnection object at 0x000002BEA1DD35C8>, 'Connection to 110.243.8.26 timed out. (connect timeout=8)'))
2020-05-15 15:02:38,870 - ip_verify.py[line:84] - INFO: ('invalid url', '110.243.8.26:9999')
2020-05-15 15:02:38,872 - ip_verify.py[line:70] - INFO: 连接错误HTTPConnectionPool(host='60.217.129.63', port=8060): Max retries exceeded with url: http://httpbin.org/get (Caused by ConnectTimeoutError(<urllib3.connection.HTTPConnection object at 0x000002BEA1DDA608>, 'Connection to 60.217.129.63 timed out. (connect timeout=8)'))
2020-05-15 15:02:38,873 - ip_verify.py[line:84] - INFO: ('invalid url', '60.217.129.63:8060')
2020-05-15 15:02:40,868 - ip_verify.py[line:67] - INFO: start connection to 139.196.193.85:8080
2020-05-15 15:02:40,876 - ip_verify.py[line:67] - INFO: start connection to 123.171.5.124:8118
2020-05-15 15:02:40,882 - ip_verify.py[line:67] - INFO: start connection to 175.148.71.139:1133
2020-05-15 15:02:40,889 - ip_verify.py[line:67] - INFO: start connection to 114.223.208.165:8118
2020-05-15 15:02:40,895 - ip_verify.py[line:67] - INFO: start connection to 114.226.35.175:8118
2020-05-15 15:02:40,901 - ip_verify.py[line:67] - INFO: start connection to 175.148.69.176:1133
2020-05-15 15:02:40,903 - ip_verify.py[line:94] - INFO: ('线程池容量', 10)
2020-05-15 15:02:40,908 - ip_verify.py[line:67] - INFO: start connection to 175.43.35.39:9999
2020-05-15 15:02:40,909 - ip_verify.py[line:95] - INFO: ('堆栈量', 1)
2020-05-15 15:02:40,914 - ip_verify.py[line:67] - INFO: start connection to 114.226.160.141:9999
2020-05-15 15:02:40,918 - ip_verify.py[line:67] - INFO: start connection to 113.195.225.130:9999
2020-05-15 15:02:40,922 - ip_verify.py[line:67] - INFO: start connection to 182.61.12.214:8888
2020-05-15 15:02:40,925 - ip_verify.py[line:67] - INFO: start connection to 113.194.30.80:9999
2020-05-15 15:02:42,028 - ip_verify.py[line:70] - INFO: 连接错误HTTPConnectionPool(host='114.223.208.165', port=8118): Max retries exceeded with url: http://httpbin.org/get (Caused by ProxyError('Cannot connect to proxy.', NewConnectionError('<urllib3.connection.HTTPConnection object at 0x000002BEA1DC6E48>: Failed to establish a new connection: [WinError 10061] 由于目标计算机积极拒绝，无法连接。')))
2020-05-15 15:02:42,028 - ip_verify.py[line:84] - INFO: ('invalid url', '114.223.208.165:8118')
2020-05-15 15:02:42,040 - ip_verify.py[line:70] - INFO: 连接错误HTTPConnectionPool(host='114.226.160.141', port=9999): Max retries exceeded with url: http://httpbin.org/get (Caused by ProxyError('Cannot connect to proxy.', NewConnectionError('<urllib3.connection.HTTPConnection object at 0x000002BEA1E11548>: Failed to establish a new connection: [WinError 10061] 由于目标计算机积极拒绝，无法连接。')))
2020-05-15 15:02:42,040 - ip_verify.py[line:84] - INFO: ('invalid url', '114.226.160.141:9999')
2020-05-15 15:02:42,067 - ip_verify.py[line:70] - INFO: 连接错误HTTPConnectionPool(host='175.148.69.176', port=1133): Max retries exceeded with url: http://httpbin.org/get (Caused by ProxyError('Cannot connect to proxy.', NewConnectionError('<urllib3.connection.HTTPConnection object at 0x000002BEA1DF5348>: Failed to establish a new connection: [WinError 10061] 由于目标计算机积极拒绝，无法连接。')))
2020-05-15 15:02:42,067 - ip_verify.py[line:84] - INFO: ('invalid url', '175.148.69.176:1133')
2020-05-15 15:02:42,073 - ip_verify.py[line:70] - INFO: 连接错误HTTPConnectionPool(host='175.148.71.139', port=1133): Max retries exceeded with url: http://httpbin.org/get (Caused by ProxyError('Cannot connect to proxy.', NewConnectionError('<urllib3.connection.HTTPConnection object at 0x000002BEA1DE9C08>: Failed to establish a new connection: [WinError 10061] 由于目标计算机积极拒绝，无法连接。')))
2020-05-15 15:02:42,073 - ip_verify.py[line:84] - INFO: ('invalid url', '175.148.71.139:1133')
2020-05-15 15:02:48,875 - ip_verify.py[line:70] - INFO: 连接错误HTTPConnectionPool(host='139.196.193.85', port=8080): Max retries exceeded with url: http://httpbin.org/get (Caused by ConnectTimeoutError(<urllib3.connection.HTTPConnection object at 0x000002BEA1DB1588>, 'Connection to 139.196.193.85 timed out. (connect timeout=8)'))
2020-05-15 15:02:48,876 - ip_verify.py[line:84] - INFO: ('invalid url', '139.196.193.85:8080')
2020-05-15 15:02:48,886 - ip_verify.py[line:70] - INFO: 连接错误HTTPConnectionPool(host='123.171.5.124', port=8118): Max retries exceeded with url: http://httpbin.org/get (Caused by ConnectTimeoutError(<urllib3.connection.HTTPConnection object at 0x000002BEA1D8E348>, 'Connection to 123.171.5.124 timed out. (connect timeout=8)'))
2020-05-15 15:02:48,887 - ip_verify.py[line:84] - INFO: ('invalid url', '123.171.5.124:8118')
2020-05-15 15:02:48,903 - ip_verify.py[line:70] - INFO: 连接错误HTTPConnectionPool(host='114.226.35.175', port=8118): Max retries exceeded with url: http://httpbin.org/get (Caused by ConnectTimeoutError(<urllib3.connection.HTTPConnection object at 0x000002BEA1DBB2C8>, 'Connection to 114.226.35.175 timed out. (connect timeout=8)'))
2020-05-15 15:02:48,904 - ip_verify.py[line:84] - INFO: ('invalid url', '114.226.35.175:8118')
2020-05-15 15:02:48,913 - ip_verify.py[line:70] - INFO: 连接错误HTTPConnectionPool(host='175.43.35.39', port=9999): Max retries exceeded with url: http://httpbin.org/get (Caused by ConnectTimeoutError(<urllib3.connection.HTTPConnection object at 0x000002BEA1DF0048>, 'Connection to 175.43.35.39 timed out. (connect timeout=8)'))
2020-05-15 15:02:48,914 - ip_verify.py[line:84] - INFO: ('invalid url', '175.43.35.39:9999')
2020-05-15 15:02:48,921 - ip_verify.py[line:70] - INFO: 连接错误HTTPConnectionPool(host='113.195.225.130', port=9999): Max retries exceeded with url: http://httpbin.org/get (Caused by ConnectTimeoutError(<urllib3.connection.HTTPConnection object at 0x000002BEA1DE3E08>, 'Connection to 113.195.225.130 timed out. (connect timeout=8)'))
2020-05-15 15:02:48,922 - ip_verify.py[line:84] - INFO: ('invalid url', '113.195.225.130:9999')
2020-05-15 15:02:48,925 - ip_verify.py[line:70] - INFO: 连接错误HTTPConnectionPool(host='182.61.12.214', port=8888): Max retries exceeded with url: http://httpbin.org/get (Caused by ConnectTimeoutError(<urllib3.connection.HTTPConnection object at 0x000002BEA17A6848>, 'Connection to 182.61.12.214 timed out. (connect timeout=8)'))
2020-05-15 15:02:48,926 - ip_verify.py[line:84] - INFO: ('invalid url', '182.61.12.214:8888')
2020-05-15 15:02:48,927 - ip_verify.py[line:70] - INFO: 连接错误HTTPConnectionPool(host='113.194.30.80', port=9999): Max retries exceeded with url: http://httpbin.org/get (Caused by ConnectTimeoutError(<urllib3.connection.HTTPConnection object at 0x000002BEA1D6A208>, 'Connection to 113.194.30.80 timed out. (connect timeout=8)'))
2020-05-15 15:02:48,928 - ip_verify.py[line:84] - INFO: ('invalid url', '113.194.30.80:9999')
2020-05-15 15:02:50,915 - ip_verify.py[line:67] - INFO: start connection to 183.166.170.208:8888
2020-05-15 15:02:50,917 - ip_verify.py[line:67] - INFO: start connection to 117.88.5.253:3000
2020-05-15 15:02:50,919 - ip_verify.py[line:67] - INFO: start connection to 60.31.213.115:808
2020-05-15 15:02:50,923 - ip_verify.py[line:67] - INFO: start connection to 171.35.147.251:9999
2020-05-15 15:02:50,926 - ip_verify.py[line:67] - INFO: start connection to 144.123.70.205:10086
2020-05-15 15:02:50,928 - ip_verify.py[line:67] - INFO: start connection to 121.237.148.106:3000
2020-05-15 15:02:50,931 - ip_verify.py[line:94] - INFO: ('线程池容量', 10)
2020-05-15 15:02:50,931 - ip_verify.py[line:67] - INFO: start connection to 117.88.5.246:3000
2020-05-15 15:02:50,931 - ip_verify.py[line:95] - INFO: ('堆栈量', 1)
2020-05-15 15:02:50,934 - ip_verify.py[line:67] - INFO: start connection to 110.243.10.182:9999
2020-05-15 15:02:50,936 - ip_verify.py[line:67] - INFO: start connection to 49.70.18.179:61234
2020-05-15 15:02:50,939 - ip_verify.py[line:67] - INFO: start connection to 121.237.149.66:3000
2020-05-15 15:02:50,941 - ip_verify.py[line:67] - INFO: start connection to 60.167.112.199:1133
2020-05-15 15:02:52,026 - ip_verify.py[line:70] - INFO: 连接错误HTTPConnectionPool(host='183.166.170.208', port=8888): Max retries exceeded with url: http://httpbin.org/get (Caused by ProxyError('Cannot connect to proxy.', NewConnectionError('<urllib3.connection.HTTPConnection object at 0x000002BEA1DC6AC8>: Failed to establish a new connection: [WinError 10061] 由于目标计算机积极拒绝，无法连接。')))
2020-05-15 15:02:52,027 - ip_verify.py[line:84] - INFO: ('invalid url', '183.166.170.208:8888')
2020-05-15 15:02:52,052 - ip_verify.py[line:70] - INFO: 连接错误HTTPConnectionPool(host='117.88.5.253', port=3000): Max retries exceeded with url: http://httpbin.org/get (Caused by ProxyError('Cannot connect to proxy.', NewConnectionError('<urllib3.connection.HTTPConnection object at 0x000002BEA1E18288>: Failed to establish a new connection: [WinError 10061] 由于目标计算机积极拒绝，无法连接。')))
2020-05-15 15:02:52,052 - ip_verify.py[line:84] - INFO: ('invalid url', '117.88.5.253:3000')
2020-05-15 15:02:52,062 - ip_verify.py[line:70] - INFO: 连接错误HTTPConnectionPool(host='117.88.5.246', port=3000): Max retries exceeded with url: http://httpbin.org/get (Caused by ProxyError('Cannot connect to proxy.', NewConnectionError('<urllib3.connection.HTTPConnection object at 0x000002BEA1DB18C8>: Failed to establish a new connection: [WinError 10061] 由于目标计算机积极拒绝，无法连接。')))
2020-05-15 15:02:52,062 - ip_verify.py[line:84] - INFO: ('invalid url', '117.88.5.246:3000')
2020-05-15 15:02:52,063 - ip_verify.py[line:70] - INFO: 连接错误HTTPConnectionPool(host='121.237.148.106', port=3000): Max retries exceeded with url: http://httpbin.org/get (Caused by ProxyError('Cannot connect to proxy.', NewConnectionError('<urllib3.connection.HTTPConnection object at 0x000002BEA1DE32C8>: Failed to establish a new connection: [WinError 10061] 由于目标计算机积极拒绝，无法连接。')))
2020-05-15 15:02:52,063 - ip_verify.py[line:84] - INFO: ('invalid url', '121.237.148.106:3000')
2020-05-15 15:02:52,066 - ip_verify.py[line:70] - INFO: 连接错误HTTPConnectionPool(host='121.237.149.66', port=3000): Max retries exceeded with url: http://httpbin.org/get (Caused by ProxyError('Cannot connect to proxy.', NewConnectionError('<urllib3.connection.HTTPConnection object at 0x000002BEA1DC2148>: Failed to establish a new connection: [WinError 10061] 由于目标计算机积极拒绝，无法连接。')))
2020-05-15 15:02:52,066 - ip_verify.py[line:84] - INFO: ('invalid url', '121.237.149.66:3000')
2020-05-15 15:02:52,106 - ip_verify.py[line:70] - INFO: 连接错误HTTPConnectionPool(host='144.123.70.205', port=10086): Max retries exceeded with url: http://httpbin.org/get (Caused by ProxyError('Cannot connect to proxy.', NewConnectionError('<urllib3.connection.HTTPConnection object at 0x000002BEA1E0A588>: Failed to establish a new connection: [WinError 10061] 由于目标计算机积极拒绝，无法连接。')))
2020-05-15 15:02:52,107 - ip_verify.py[line:84] - INFO: ('invalid url', '144.123.70.205:10086')
2020-05-15 15:02:58,922 - ip_verify.py[line:70] - INFO: 连接错误HTTPConnectionPool(host='60.31.213.115', port=808): Max retries exceeded with url: http://httpbin.org/get (Caused by ConnectTimeoutError(<urllib3.connection.HTTPConnection object at 0x000002BEA1DB3748>, 'Connection to 60.31.213.115 timed out. (connect timeout=8)'))
2020-05-15 15:02:58,922 - ip_verify.py[line:84] - INFO: ('invalid url', '60.31.213.115:808')
2020-05-15 15:02:58,925 - ip_verify.py[line:70] - INFO: 连接错误HTTPConnectionPool(host='171.35.147.251', port=9999): Max retries exceeded with url: http://httpbin.org/get (Caused by ConnectTimeoutError(<urllib3.connection.HTTPConnection object at 0x000002BEA1DD7E88>, 'Connection to 171.35.147.251 timed out. (connect timeout=8)'))
2020-05-15 15:02:58,925 - ip_verify.py[line:84] - INFO: ('invalid url', '171.35.147.251:9999')
2020-05-15 15:02:58,936 - ip_verify.py[line:70] - INFO: 连接错误HTTPConnectionPool(host='110.243.10.182', port=9999): Max retries exceeded with url: http://httpbin.org/get (Caused by ConnectTimeoutError(<urllib3.connection.HTTPConnection object at 0x000002BEA1DBB608>, 'Connection to 110.243.10.182 timed out. (connect timeout=8)'))
2020-05-15 15:02:58,936 - ip_verify.py[line:84] - INFO: ('invalid url', '110.243.10.182:9999')
2020-05-15 15:02:58,938 - ip_verify.py[line:70] - INFO: 连接错误HTTPConnectionPool(host='49.70.18.179', port=61234): Max retries exceeded with url: http://httpbin.org/get (Caused by ConnectTimeoutError(<urllib3.connection.HTTPConnection object at 0x000002BEA1DCD748>, 'Connection to 49.70.18.179 timed out. (connect timeout=8)'))
2020-05-15 15:02:58,938 - ip_verify.py[line:84] - INFO: ('invalid url', '49.70.18.179:61234')
2020-05-15 15:02:58,943 - ip_verify.py[line:70] - INFO: 连接错误HTTPConnectionPool(host='60.167.112.199', port=1133): Max retries exceeded with url: http://httpbin.org/get (Caused by ConnectTimeoutError(<urllib3.connection.HTTPConnection object at 0x000002BEA1E11148>, 'Connection to 60.167.112.199 timed out. (connect timeout=8)'))
2020-05-15 15:02:58,943 - ip_verify.py[line:84] - INFO: ('invalid url', '60.167.112.199:1133')
2020-05-15 15:03:00,936 - ip_verify.py[line:67] - INFO: start connection to 121.237.148.101:3000
2020-05-15 15:03:00,939 - ip_verify.py[line:67] - INFO: start connection to 221.193.94.18:8118
2020-05-15 15:03:00,941 - ip_verify.py[line:67] - INFO: start connection to 121.237.148.183:3000
2020-05-15 15:03:00,945 - ip_verify.py[line:67] - INFO: start connection to 171.11.33.58:9999
2020-05-15 15:03:00,948 - ip_verify.py[line:67] - INFO: start connection to 113.194.28.11:9999
2020-05-15 15:03:00,951 - ip_verify.py[line:67] - INFO: start connection to 113.195.168.115:48888
2020-05-15 15:03:00,951 - ip_verify.py[line:94] - INFO: ('线程池容量', 10)
2020-05-15 15:03:00,953 - ip_verify.py[line:95] - INFO: ('堆栈量', 1)
2020-05-15 15:03:00,954 - ip_verify.py[line:67] - INFO: start connection to 118.113.247.115:9999
2020-05-15 15:03:00,956 - ip_verify.py[line:67] - INFO: start connection to 60.167.112.236:1133
2020-05-15 15:03:00,958 - ip_verify.py[line:67] - INFO: start connection to 117.88.177.101:3000
2020-05-15 15:03:00,961 - ip_verify.py[line:67] - INFO: start connection to 183.166.136.144:8888
2020-05-15 15:03:00,963 - ip_verify.py[line:67] - INFO: start connection to 27.208.231.100:8060
2020-05-15 15:03:01,982 - ip_verify.py[line:70] - INFO: 连接错误HTTPConnectionPool(host='118.113.247.115', port=9999): Max retries exceeded with url: http://httpbin.org/get (Caused by ProxyError('Cannot connect to proxy.', NewConnectionError('<urllib3.connection.HTTPConnection object at 0x000002BEA1DD3C48>: Failed to establish a new connection: [WinError 10061] 由于目标计算机积极拒绝，无法连接。')))
2020-05-15 15:03:01,982 - ip_verify.py[line:84] - INFO: ('invalid url', '118.113.247.115:9999')
2020-05-15 15:03:02,086 - ip_verify.py[line:70] - INFO: 连接错误HTTPConnectionPool(host='183.166.136.144', port=8888): Max retries exceeded with url: http://httpbin.org/get (Caused by ProxyError('Cannot connect to proxy.', NewConnectionError('<urllib3.connection.HTTPConnection object at 0x000002BEA1DF0348>: Failed to establish a new connection: [WinError 10061] 由于目标计算机积极拒绝，无法连接。')))
2020-05-15 15:03:02,086 - ip_verify.py[line:84] - INFO: ('invalid url', '183.166.136.144:8888')
2020-05-15 15:03:08,938 - ip_verify.py[line:70] - INFO: 连接错误HTTPConnectionPool(host='121.237.148.101', port=3000): Max retries exceeded with url: http://httpbin.org/get (Caused by ConnectTimeoutError(<urllib3.connection.HTTPConnection object at 0x000002BEA1DF5308>, 'Connection to 121.237.148.101 timed out. (connect timeout=8)'))
2020-05-15 15:03:08,938 - ip_verify.py[line:84] - INFO: ('invalid url', '121.237.148.101:3000')
2020-05-15 15:03:08,941 - ip_verify.py[line:70] - INFO: 连接错误HTTPConnectionPool(host='221.193.94.18', port=8118): Max retries exceeded with url: http://httpbin.org/get (Caused by ConnectTimeoutError(<urllib3.connection.HTTPConnection object at 0x000002BEA1DDA288>, 'Connection to 221.193.94.18 timed out. (connect timeout=8)'))
2020-05-15 15:03:08,941 - ip_verify.py[line:84] - INFO: ('invalid url', '221.193.94.18:8118')
2020-05-15 15:03:08,944 - ip_verify.py[line:70] - INFO: 连接错误HTTPConnectionPool(host='121.237.148.183', port=3000): Max retries exceeded with url: http://httpbin.org/get (Caused by ConnectTimeoutError(<urllib3.connection.HTTPConnection object at 0x000002BEA1DAACC8>, 'Connection to 121.237.148.183 timed out. (connect timeout=8)'))
2020-05-15 15:03:08,944 - ip_verify.py[line:84] - INFO: ('invalid url', '121.237.148.183:3000')
2020-05-15 15:03:08,947 - ip_verify.py[line:70] - INFO: 连接错误HTTPConnectionPool(host='171.11.33.58', port=9999): Max retries exceeded with url: http://httpbin.org/get (Caused by ConnectTimeoutError(<urllib3.connection.HTTPConnection object at 0x000002BEA1DC6248>, 'Connection to 171.11.33.58 timed out. (connect timeout=8)'))
2020-05-15 15:03:08,947 - ip_verify.py[line:84] - INFO: ('invalid url', '171.11.33.58:9999')
2020-05-15 15:03:08,951 - ip_verify.py[line:70] - INFO: 连接错误HTTPConnectionPool(host='113.194.28.11', port=9999): Max retries exceeded with url: http://httpbin.org/get (Caused by ConnectTimeoutError(<urllib3.connection.HTTPConnection object at 0x000002BEA1E21688>, 'Connection to 113.194.28.11 timed out. (connect timeout=8)'))
2020-05-15 15:03:08,951 - ip_verify.py[line:84] - INFO: ('invalid url', '113.194.28.11:9999')
2020-05-15 15:03:08,954 - ip_verify.py[line:70] - INFO: 连接错误HTTPConnectionPool(host='113.195.168.115', port=48888): Max retries exceeded with url: http://httpbin.org/get (Caused by ConnectTimeoutError(<urllib3.connection.HTTPConnection object at 0x000002BEA1DC2E48>, 'Connection to 113.195.168.115 timed out. (connect timeout=8)'))
2020-05-15 15:03:08,954 - ip_verify.py[line:84] - INFO: ('invalid url', '113.195.168.115:48888')
2020-05-15 15:03:08,958 - ip_verify.py[line:70] - INFO: 连接错误HTTPConnectionPool(host='60.167.112.236', port=1133): Max retries exceeded with url: http://httpbin.org/get (Caused by ConnectTimeoutError(<urllib3.connection.HTTPConnection object at 0x000002BEA1E0CCC8>, 'Connection to 60.167.112.236 timed out. (connect timeout=8)'))
2020-05-15 15:03:08,958 - ip_verify.py[line:84] - INFO: ('invalid url', '60.167.112.236:1133')
2020-05-15 15:03:08,961 - ip_verify.py[line:70] - INFO: 连接错误HTTPConnectionPool(host='117.88.177.101', port=3000): Max retries exceeded with url: http://httpbin.org/get (Caused by ConnectTimeoutError(<urllib3.connection.HTTPConnection object at 0x000002BEA1DD7308>, 'Connection to 117.88.177.101 timed out. (connect timeout=8)'))
2020-05-15 15:03:08,961 - ip_verify.py[line:84] - INFO: ('invalid url', '117.88.177.101:3000')
2020-05-15 15:03:08,965 - ip_verify.py[line:70] - INFO: 连接错误HTTPConnectionPool(host='27.208.231.100', port=8060): Max retries exceeded with url: http://httpbin.org/get (Caused by ConnectTimeoutError(<urllib3.connection.HTTPConnection object at 0x000002BEA1DA5D88>, 'Connection to 27.208.231.100 timed out. (connect timeout=8)'))
2020-05-15 15:03:08,965 - ip_verify.py[line:84] - INFO: ('invalid url', '27.208.231.100:8060')
2020-05-15 15:03:10,958 - ip_verify.py[line:67] - INFO: start connection to 123.169.99.177:9999
2020-05-15 15:03:10,961 - ip_verify.py[line:67] - INFO: start connection to 119.4.13.26:1133
2020-05-15 15:03:10,964 - ip_verify.py[line:67] - INFO: start connection to 58.253.158.177:9999
2020-05-15 15:03:10,967 - ip_verify.py[line:67] - INFO: start connection to 112.84.73.53:9999
2020-05-15 15:03:10,969 - ip_verify.py[line:67] - INFO: start connection to 221.237.37.137:8118
2020-05-15 15:03:10,971 - ip_verify.py[line:67] - INFO: start connection to 117.45.139.84:9006
2020-05-15 15:03:10,974 - ip_verify.py[line:67] - INFO: start connection to 171.35.86.72:8118
2020-05-15 15:03:10,977 - ip_verify.py[line:67] - INFO: start connection to 49.235.246.24:8118
2020-05-15 15:03:10,978 - ip_verify.py[line:94] - INFO: ('线程池容量', 10)
2020-05-15 15:03:10,979 - ip_verify.py[line:95] - INFO: ('堆栈量', 1)
2020-05-15 15:03:10,980 - ip_verify.py[line:67] - INFO: start connection to 60.188.65.73:3000
2020-05-15 15:03:10,982 - ip_verify.py[line:67] - INFO: start connection to 175.148.69.26:1133
2020-05-15 15:03:10,985 - ip_verify.py[line:67] - INFO: start connection to 183.166.103.164:9999
2020-05-15 15:03:11,192 - ip_verify.py[line:70] - INFO: 连接错误("Connection broken: ConnectionResetError(10054, '远程主机强迫关闭了一个现有的连接。', None, 10054, None)", ConnectionResetError(10054, '远程主机强迫关闭了一个现有的连接。', None, 10054, None))
2020-05-15 15:03:11,192 - ip_verify.py[line:84] - INFO: ('invalid url', '49.235.246.24:8118')
2020-05-15 15:03:12,090 - ip_verify.py[line:70] - INFO: 连接错误HTTPConnectionPool(host='117.45.139.84', port=9006): Max retries exceeded with url: http://httpbin.org/get (Caused by ProxyError('Cannot connect to proxy.', NewConnectionError('<urllib3.connection.HTTPConnection object at 0x000002BEA1E21708>: Failed to establish a new connection: [WinError 10061] 由于目标计算机积极拒绝，无法连接。')))
2020-05-15 15:03:12,090 - ip_verify.py[line:84] - INFO: ('invalid url', '117.45.139.84:9006')
2020-05-15 15:03:18,960 - ip_verify.py[line:70] - INFO: 连接错误HTTPConnectionPool(host='123.169.99.177', port=9999): Max retries exceeded with url: http://httpbin.org/get (Caused by ConnectTimeoutError(<urllib3.connection.HTTPConnection object at 0x000002BEA1DBB408>, 'Connection to 123.169.99.177 timed out. (connect timeout=8)'))
2020-05-15 15:03:18,960 - ip_verify.py[line:84] - INFO: ('invalid url', '123.169.99.177:9999')
2020-05-15 15:03:18,963 - ip_verify.py[line:70] - INFO: 连接错误HTTPConnectionPool(host='119.4.13.26', port=1133): Max retries exceeded with url: http://httpbin.org/get (Caused by ConnectTimeoutError(<urllib3.connection.HTTPConnection object at 0x000002BEA1D8E348>, 'Connection to 119.4.13.26 timed out. (connect timeout=8)'))
2020-05-15 15:03:18,963 - ip_verify.py[line:84] - INFO: ('invalid url', '119.4.13.26:1133')
2020-05-15 15:03:18,965 - ip_verify.py[line:70] - INFO: 连接错误HTTPConnectionPool(host='58.253.158.177', port=9999): Max retries exceeded with url: http://httpbin.org/get (Caused by ConnectTimeoutError(<urllib3.connection.HTTPConnection object at 0x000002BEA1DC6148>, 'Connection to 58.253.158.177 timed out. (connect timeout=8)'))
2020-05-15 15:03:18,965 - ip_verify.py[line:84] - INFO: ('invalid url', '58.253.158.177:9999')
2020-05-15 15:03:18,969 - ip_verify.py[line:70] - INFO: 连接错误HTTPConnectionPool(host='112.84.73.53', port=9999): Max retries exceeded with url: http://httpbin.org/get (Caused by ConnectTimeoutError(<urllib3.connection.HTTPConnection object at 0x000002BEA1E18448>, 'Connection to 112.84.73.53 timed out. (connect timeout=8)'))
2020-05-15 15:03:18,969 - ip_verify.py[line:84] - INFO: ('invalid url', '112.84.73.53:9999')
2020-05-15 15:03:18,971 - ip_verify.py[line:70] - INFO: 连接错误HTTPConnectionPool(host='221.237.37.137', port=8118): Max retries exceeded with url: http://httpbin.org/get (Caused by ConnectTimeoutError(<urllib3.connection.HTTPConnection object at 0x000002BEA1E0A8C8>, 'Connection to 221.237.37.137 timed out. (connect timeout=8)'))
2020-05-15 15:03:18,971 - ip_verify.py[line:84] - INFO: ('invalid url', '221.237.37.137:8118')
2020-05-15 15:03:18,976 - ip_verify.py[line:70] - INFO: 连接错误HTTPConnectionPool(host='171.35.86.72', port=8118): Max retries exceeded with url: http://httpbin.org/get (Caused by ConnectTimeoutError(<urllib3.connection.HTTPConnection object at 0x000002BEA1DAA908>, 'Connection to 171.35.86.72 timed out. (connect timeout=8)'))
2020-05-15 15:03:18,976 - ip_verify.py[line:84] - INFO: ('invalid url', '171.35.86.72:8118')
2020-05-15 15:03:18,981 - ip_verify.py[line:70] - INFO: 连接错误HTTPConnectionPool(host='60.188.65.73', port=3000): Max retries exceeded with url: http://httpbin.org/get (Caused by ConnectTimeoutError(<urllib3.connection.HTTPConnection object at 0x000002BEA1D78A08>, 'Connection to 60.188.65.73 timed out. (connect timeout=8)'))
2020-05-15 15:03:18,981 - ip_verify.py[line:84] - INFO: ('invalid url', '60.188.65.73:3000')
2020-05-15 15:03:18,984 - ip_verify.py[line:70] - INFO: 连接错误HTTPConnectionPool(host='175.148.69.26', port=1133): Max retries exceeded with url: http://httpbin.org/get (Caused by ConnectTimeoutError(<urllib3.connection.HTTPConnection object at 0x000002BEA1E18588>, 'Connection to 175.148.69.26 timed out. (connect timeout=8)'))
2020-05-15 15:03:18,984 - ip_verify.py[line:84] - INFO: ('invalid url', '175.148.69.26:1133')
2020-05-15 15:03:18,986 - ip_verify.py[line:70] - INFO: 连接错误HTTPConnectionPool(host='183.166.103.164', port=9999): Max retries exceeded with url: http://httpbin.org/get (Caused by ConnectTimeoutError(<urllib3.connection.HTTPConnection object at 0x000002BEA1DCD3C8>, 'Connection to 183.166.103.164 timed out. (connect timeout=8)'))
2020-05-15 15:03:18,986 - ip_verify.py[line:84] - INFO: ('invalid url', '183.166.103.164:9999')
2020-05-15 15:03:20,985 - ip_verify.py[line:67] - INFO: start connection to 113.195.225.68:9999
2020-05-15 15:03:20,991 - ip_verify.py[line:67] - INFO: start connection to 117.88.176.123:3000
2020-05-15 15:03:20,995 - ip_verify.py[line:67] - INFO: start connection to 175.148.68.175:1133
2020-05-15 15:03:20,998 - ip_verify.py[line:67] - INFO: start connection to 171.35.163.132:9999
2020-05-15 15:03:21,001 - ip_verify.py[line:67] - INFO: start connection to 117.88.177.24:3000
2020-05-15 15:03:21,003 - ip_verify.py[line:67] - INFO: start connection to 121.237.148.135:3000
2020-05-15 15:03:21,006 - ip_verify.py[line:67] - INFO: start connection to 121.237.149.220:3000
2020-05-15 15:03:21,007 - ip_verify.py[line:94] - INFO: ('线程池容量', 10)
2020-05-15 15:03:21,009 - ip_verify.py[line:95] - INFO: ('堆栈量', 1)
2020-05-15 15:03:21,009 - ip_verify.py[line:67] - INFO: start connection to 110.243.5.40:9999
2020-05-15 15:03:21,012 - ip_verify.py[line:67] - INFO: start connection to 122.4.40.194:27430
2020-05-15 15:03:21,015 - ip_verify.py[line:67] - INFO: start connection to 115.49.74.102:8118
2020-05-15 15:03:21,018 - ip_verify.py[line:67] - INFO: start connection to 101.200.81.61:80
2020-05-15 15:03:21,140 - ip_verify.py[line:72] - INFO: 
2020-05-15 15:03:21,140 - ip_verify.py[line:84] - INFO: ('invalid url', '101.200.81.61:80')
2020-05-15 15:03:22,128 - ip_verify.py[line:70] - INFO: 连接错误HTTPConnectionPool(host='121.237.149.220', port=3000): Max retries exceeded with url: http://httpbin.org/get (Caused by ProxyError('Cannot connect to proxy.', NewConnectionError('<urllib3.connection.HTTPConnection object at 0x000002BEA1E11908>: Failed to establish a new connection: [WinError 10061] 由于目标计算机积极拒绝，无法连接。')))
2020-05-15 15:03:22,128 - ip_verify.py[line:84] - INFO: ('invalid url', '121.237.149.220:3000')
2020-05-15 15:03:22,128 - ip_verify.py[line:70] - INFO: 连接错误HTTPConnectionPool(host='113.195.225.68', port=9999): Max retries exceeded with url: http://httpbin.org/get (Caused by ProxyError('Cannot connect to proxy.', NewConnectionError('<urllib3.connection.HTTPConnection object at 0x000002BEA1DF9E48>: Failed to establish a new connection: [WinError 10061] 由于目标计算机积极拒绝，无法连接。')))
2020-05-15 15:03:22,129 - ip_verify.py[line:84] - INFO: ('invalid url', '113.195.225.68:9999')
2020-05-15 15:03:22,156 - ip_verify.py[line:70] - INFO: 连接错误HTTPConnectionPool(host='171.35.163.132', port=9999): Max retries exceeded with url: http://httpbin.org/get (Caused by ProxyError('Cannot connect to proxy.', NewConnectionError('<urllib3.connection.HTTPConnection object at 0x000002BEA1DF0948>: Failed to establish a new connection: [WinError 10061] 由于目标计算机积极拒绝，无法连接。')))
2020-05-15 15:03:22,156 - ip_verify.py[line:84] - INFO: ('invalid url', '171.35.163.132:9999')
2020-05-15 15:03:22,195 - ip_verify.py[line:70] - INFO: 连接错误HTTPConnectionPool(host='122.4.40.194', port=27430): Max retries exceeded with url: http://httpbin.org/get (Caused by ProxyError('Cannot connect to proxy.', NewConnectionError('<urllib3.connection.HTTPConnection object at 0x000002BEA1D8EF48>: Failed to establish a new connection: [WinError 10061] 由于目标计算机积极拒绝，无法连接。')))
2020-05-15 15:03:22,196 - ip_verify.py[line:84] - INFO: ('invalid url', '122.4.40.194:27430')
2020-05-15 15:03:28,993 - ip_verify.py[line:70] - INFO: 连接错误HTTPConnectionPool(host='117.88.176.123', port=3000): Max retries exceeded with url: http://httpbin.org/get (Caused by ConnectTimeoutError(<urllib3.connection.HTTPConnection object at 0x000002BEA1DC2D48>, 'Connection to 117.88.176.123 timed out. (connect timeout=8)'))
2020-05-15 15:03:28,993 - ip_verify.py[line:84] - INFO: ('invalid url', '117.88.176.123:3000')
2020-05-15 15:03:28,998 - ip_verify.py[line:70] - INFO: 连接错误HTTPConnectionPool(host='175.148.68.175', port=1133): Max retries exceeded with url: http://httpbin.org/get (Caused by ConnectTimeoutError(<urllib3.connection.HTTPConnection object at 0x000002BEA1E0C208>, 'Connection to 175.148.68.175 timed out. (connect timeout=8)'))
2020-05-15 15:03:28,998 - ip_verify.py[line:84] - INFO: ('invalid url', '175.148.68.175:1133')
2020-05-15 15:03:29,006 - ip_verify.py[line:70] - INFO: 连接错误HTTPConnectionPool(host='117.88.177.24', port=3000): Max retries exceeded with url: http://httpbin.org/get (Caused by ConnectTimeoutError(<urllib3.connection.HTTPConnection object at 0x000002BEA1DF58C8>, 'Connection to 117.88.177.24 timed out. (connect timeout=8)'))
2020-05-15 15:03:29,006 - ip_verify.py[line:84] - INFO: ('invalid url', '117.88.177.24:3000')
2020-05-15 15:03:29,006 - ip_verify.py[line:70] - INFO: 连接错误HTTPConnectionPool(host='121.237.148.135', port=3000): Max retries exceeded with url: http://httpbin.org/get (Caused by ConnectTimeoutError(<urllib3.connection.HTTPConnection object at 0x000002BEA1DDA388>, 'Connection to 121.237.148.135 timed out. (connect timeout=8)'))
2020-05-15 15:03:29,006 - ip_verify.py[line:84] - INFO: ('invalid url', '121.237.148.135:3000')
2020-05-15 15:03:29,011 - ip_verify.py[line:70] - INFO: 连接错误HTTPConnectionPool(host='110.243.5.40', port=9999): Max retries exceeded with url: http://httpbin.org/get (Caused by ConnectTimeoutError(<urllib3.connection.HTTPConnection object at 0x000002BEA1DB1A48>, 'Connection to 110.243.5.40 timed out. (connect timeout=8)'))
2020-05-15 15:03:29,011 - ip_verify.py[line:84] - INFO: ('invalid url', '110.243.5.40:9999')
2020-05-15 15:03:29,017 - ip_verify.py[line:70] - INFO: 连接错误HTTPConnectionPool(host='115.49.74.102', port=8118): Max retries exceeded with url: http://httpbin.org/get (Caused by ConnectTimeoutError(<urllib3.connection.HTTPConnection object at 0x000002BEA1DA5348>, 'Connection to 115.49.74.102 timed out. (connect timeout=8)'))
2020-05-15 15:03:29,017 - ip_verify.py[line:84] - INFO: ('invalid url', '115.49.74.102:8118')
2020-05-15 15:03:31,012 - ip_verify.py[line:67] - INFO: start connection to 49.76.237.243:8123
2020-05-15 15:03:31,016 - ip_verify.py[line:67] - INFO: start connection to 117.88.176.221:3000
2020-05-15 15:07:52,550 - redis_memory.py[line:65] - INFO: ('set row', '111.222.141.127:8118')
2020-05-15 15:07:52,552 - redis_memory.py[line:65] - INFO: ('set row', '125.124.205.140:808')
2020-05-15 15:07:52,554 - redis_memory.py[line:65] - INFO: ('set row', '60.188.2.195:3000')
2020-05-15 15:07:52,556 - redis_memory.py[line:65] - INFO: ('set row', '125.126.115.25:60004')
2020-05-15 15:07:52,557 - redis_memory.py[line:65] - INFO: ('set row', '125.126.115.229:60004')
2020-05-15 15:07:52,559 - redis_memory.py[line:65] - INFO: ('set row', '125.126.115.116:60004')
2020-05-15 15:07:52,561 - redis_memory.py[line:65] - INFO: ('set row', '125.126.126.124:60004')
2020-05-15 15:07:52,563 - redis_memory.py[line:65] - INFO: ('set row', '125.126.109.20:60004')
2020-05-15 15:07:52,565 - redis_memory.py[line:65] - INFO: ('set row', '125.126.110.182:60004')
2020-05-15 15:07:52,567 - redis_memory.py[line:65] - INFO: ('set row', '223.241.22.237:30001')
2020-05-15 15:07:52,569 - redis_memory.py[line:65] - INFO: ('set row', '183.166.252.187:4216')
2020-05-15 15:07:52,571 - redis_memory.py[line:65] - INFO: ('set row', '183.166.241.212:4216')
2020-05-15 15:07:52,573 - redis_memory.py[line:65] - INFO: ('set row', '58.246.142.79:8118')
2020-05-15 15:07:52,576 - redis_memory.py[line:65] - INFO: ('set row', '211.159.219.225:8118')
2020-05-15 15:07:52,579 - redis_memory.py[line:65] - INFO: ('set row', '60.188.65.81:3000')
2020-05-15 15:07:52,581 - redis_memory.py[line:65] - INFO: ('set row', '119.120.248.179:4216')
2020-05-15 15:07:52,582 - redis_memory.py[line:65] - INFO: ('set row', '60.188.12.39:3000')
2020-05-15 15:07:52,584 - redis_memory.py[line:65] - INFO: ('set row', '180.122.148.223:3000')
2020-05-15 15:07:52,586 - redis_memory.py[line:65] - INFO: ('set row', '106.75.63.137:8118')
2020-05-15 15:07:52,588 - redis_memory.py[line:65] - INFO: ('set row', '223.241.4.162:4216')
2020-05-15 15:07:52,590 - redis_memory.py[line:65] - INFO: ('set row', '223.247.93.169:4216')
2020-05-15 15:07:52,593 - redis_memory.py[line:65] - INFO: ('set row', '223.241.2.84:4216')
2020-05-15 15:07:52,595 - redis_memory.py[line:65] - INFO: ('set row', '223.241.2.88:4216')
2020-05-15 15:07:52,597 - redis_memory.py[line:65] - INFO: ('set row', '183.236.234.44:38070')
2020-05-15 15:07:52,598 - redis_memory.py[line:65] - INFO: ('set row', '223.241.2.206:4216')
2020-05-15 15:07:52,600 - redis_memory.py[line:65] - INFO: ('set row', '218.75.69.50:39590')
2020-05-15 15:07:52,602 - redis_memory.py[line:65] - INFO: ('set row', '115.238.59.86:53400')
2020-05-15 15:07:52,605 - redis_memory.py[line:65] - INFO: ('set row', '125.123.157.177:3000')
2020-05-15 15:07:52,607 - redis_memory.py[line:65] - INFO: ('set row', '222.180.24.13:808')
2020-05-15 15:07:52,610 - redis_memory.py[line:65] - INFO: ('set row', '58.215.219.2:8000')
2020-05-15 15:07:52,612 - redis_memory.py[line:65] - INFO: ('set row', '117.67.126.98:4216')
2020-05-15 15:07:52,615 - redis_memory.py[line:65] - INFO: ('set row', '60.188.27.32:3000')
2020-05-15 15:07:52,617 - redis_memory.py[line:65] - INFO: ('set row', '115.219.112.34:3000')
2020-05-15 15:07:52,619 - redis_memory.py[line:65] - INFO: ('set row', '112.14.47.6:52024')
2020-05-15 15:07:52,621 - redis_memory.py[line:65] - INFO: ('set row', '60.188.241.88:3000')
2020-05-15 15:07:52,623 - redis_memory.py[line:65] - INFO: ('set row', '60.188.19.119:3000')
2020-05-15 15:07:52,624 - redis_memory.py[line:65] - INFO: ('set row', '223.241.2.172:4216')
2020-05-15 15:07:52,628 - redis_memory.py[line:65] - INFO: ('set row', '115.219.119.147:3000')
2020-05-15 15:07:52,630 - redis_memory.py[line:65] - INFO: ('set row', '120.76.116.167:8118')
2020-05-15 15:07:52,631 - redis_memory.py[line:65] - INFO: ('set row', '220.189.99.192:3000')
2020-05-15 15:07:52,634 - redis_memory.py[line:65] - INFO: ('set row', '120.79.139.253:8080')
2020-05-15 15:07:52,637 - redis_memory.py[line:65] - INFO: ('set row', '60.188.22.105:3000')
2020-05-15 15:07:52,639 - redis_memory.py[line:65] - INFO: ('set row', '60.188.240.217:3000')
2020-05-15 15:07:52,642 - redis_memory.py[line:65] - INFO: ('set row', '36.57.86.55:4216')
2020-05-15 15:07:52,644 - redis_memory.py[line:65] - INFO: ('set row', '120.198.76.45:41443')
2020-05-15 15:07:52,646 - redis_memory.py[line:65] - INFO: ('set row', '221.1.200.242:38652')
2020-05-15 15:07:52,649 - redis_memory.py[line:65] - INFO: ('set row', '114.99.54.65:8118')
2020-05-15 15:07:52,651 - redis_memory.py[line:65] - INFO: ('set row', '61.164.39.66:53281')
2020-05-15 15:07:52,652 - redis_memory.py[line:65] - INFO: ('set row', '223.241.2.176:4216')
2020-05-15 15:07:52,656 - redis_memory.py[line:65] - INFO: ('set row', '60.188.77.199:3000')
2020-05-15 15:07:52,658 - redis_memory.py[line:65] - INFO: ('set row', '223.241.2.139:4216')
2020-05-15 15:07:52,662 - redis_memory.py[line:65] - INFO: ('set row', '223.241.2.224:4216')
2020-05-15 15:07:52,663 - redis_memory.py[line:65] - INFO: ('set row', '223.241.2.247:4216')
2020-05-15 15:07:52,667 - redis_memory.py[line:65] - INFO: ('set row', '115.219.112.153:3000')
2020-05-15 15:07:52,670 - redis_memory.py[line:65] - INFO: ('set row', '223.241.2.200:4216')
2020-05-15 15:07:52,674 - redis_memory.py[line:65] - INFO: ('set row', '180.123.169.14:4216')
2020-05-15 15:07:52,676 - redis_memory.py[line:65] - INFO: ('set row', '113.12.202.50:40498')
2020-05-15 15:07:52,679 - redis_memory.py[line:65] - INFO: ('set row', '117.69.150.42:4216')
2020-05-15 15:07:52,682 - redis_memory.py[line:65] - INFO: ('set row', '106.14.206.26:8118')
2020-05-15 15:07:52,686 - redis_memory.py[line:65] - INFO: ('set row', '116.22.48.178:4216')
2020-05-15 15:07:52,688 - redis_memory.py[line:65] - INFO: ('set row', '61.140.28.56:4216')
2020-05-15 15:07:52,691 - redis_memory.py[line:65] - INFO: ('set row', '115.219.115.74:3000')
2020-05-15 15:07:52,694 - redis_memory.py[line:65] - INFO: ('set row', '114.217.58.251:3000')
2020-05-15 15:07:52,697 - redis_memory.py[line:65] - INFO: ('set row', '115.219.114.200:3000')
2020-05-15 15:07:52,700 - redis_memory.py[line:65] - INFO: ('set row', '60.188.1.48:3000')
2020-05-15 15:07:52,703 - redis_memory.py[line:65] - INFO: ('set row', '60.188.82.82:3000')
2020-05-15 15:07:52,705 - redis_memory.py[line:65] - INFO: ('set row', '124.93.201.59:59618')
2020-05-15 15:07:52,708 - redis_memory.py[line:65] - INFO: ('set row', '60.255.186.169:8888')
2020-05-15 15:07:52,711 - redis_memory.py[line:65] - INFO: ('set row', '60.188.3.119:3000')
2020-05-15 15:07:52,715 - redis_memory.py[line:65] - INFO: ('set row', '27.184.140.70:8118')
2020-05-15 15:07:52,718 - redis_memory.py[line:65] - INFO: ('set row', '60.188.79.155:3000')
2020-05-15 15:07:52,721 - redis_memory.py[line:65] - INFO: ('set row', '118.187.58.34:53281')
2020-05-15 15:07:52,724 - redis_memory.py[line:65] - INFO: ('set row', '60.188.21.120:3000')
2020-05-15 15:07:52,727 - redis_memory.py[line:65] - INFO: ('set row', '49.74.22.224:8118')
2020-05-15 15:07:52,729 - redis_memory.py[line:65] - INFO: ('set row', '60.188.19.44:3000')
2020-05-15 15:07:52,731 - redis_memory.py[line:65] - INFO: ('set row', '183.162.166.120:4216')
2020-05-15 15:07:52,734 - redis_memory.py[line:65] - INFO: ('set row', '60.188.248.190:3000')
2020-05-15 15:07:52,737 - redis_memory.py[line:65] - INFO: ('set row', '60.2.44.182:30963')
2020-05-15 15:07:52,740 - redis_memory.py[line:65] - INFO: ('set row', '60.188.245.240:3000')
2020-05-15 15:07:52,744 - redis_memory.py[line:65] - INFO: ('set row', '113.208.115.190:8118')
2020-05-15 15:07:52,747 - redis_memory.py[line:65] - INFO: ('set row', '60.189.202.77:3000')
2020-05-15 15:07:52,750 - redis_memory.py[line:65] - INFO: ('set row', '60.188.22.204:3000')
2020-05-15 15:07:52,753 - redis_memory.py[line:65] - INFO: ('set row', '60.188.76.153:3000')
2020-05-15 15:07:52,755 - redis_memory.py[line:65] - INFO: ('set row', '60.188.241.70:3000')
2020-05-15 15:07:52,759 - redis_memory.py[line:65] - INFO: ('set row', '60.188.9.27:3000')
2020-05-15 15:07:52,762 - redis_memory.py[line:65] - INFO: ('set row', '183.166.250.137:4216')
2020-05-15 15:07:52,765 - redis_memory.py[line:65] - INFO: ('set row', '49.85.96.51:3000')
2020-05-15 15:07:52,767 - redis_memory.py[line:65] - INFO: ('set row', '223.243.5.155:4216')
2020-05-15 15:07:52,770 - redis_memory.py[line:65] - INFO: ('set row', '183.162.167.117:4216')
2020-05-15 15:07:52,774 - redis_memory.py[line:65] - INFO: ('set row', '223.241.4.226:4216')
2020-05-15 15:07:52,777 - redis_memory.py[line:65] - INFO: ('set row', '223.243.5.183:4216')
2020-05-15 15:07:52,780 - redis_memory.py[line:65] - INFO: ('set row', '183.162.166.250:4216')
2020-05-15 15:07:52,784 - redis_memory.py[line:65] - INFO: ('set row', '183.162.166.35:4216')
2020-05-15 15:07:52,787 - redis_memory.py[line:65] - INFO: ('set row', '49.85.75.27:3000')
2020-05-15 15:07:52,789 - redis_memory.py[line:65] - INFO: ('set row', '180.124.86.4:4216')
2020-05-15 15:07:52,792 - redis_memory.py[line:65] - INFO: ('set row', '60.188.22.150:3000')
2020-05-15 15:07:52,796 - redis_memory.py[line:65] - INFO: ('set row', '60.188.242.165:3000')
2020-05-15 15:07:52,799 - redis_memory.py[line:65] - INFO: ('set row', '114.98.163.246:30001')
2020-05-15 15:07:52,802 - redis_memory.py[line:65] - INFO: ('set row', '60.188.4.145:3000')
2020-05-15 15:07:52,804 - redis_memory.py[line:65] - INFO: ('set row', '60.188.19.206:3000')
2020-05-15 15:07:52,808 - redis_memory.py[line:69] - INFO: ('flush', 'xici:xici_proxy_queue', 'exp', 600, 'remove count', 0)
2020-05-15 15:07:56,811 - redis_memory.py[line:69] - INFO: ('flush', 'xici:xici_proxy_queue', 'exp', 600, 'remove count', 0)
2020-05-15 15:08:00,817 - redis_memory.py[line:69] - INFO: ('flush', 'xici:xici_proxy_queue', 'exp', 600, 'remove count', 0)
2020-05-15 15:08:04,821 - redis_memory.py[line:69] - INFO: ('flush', 'xici:xici_proxy_queue', 'exp', 600, 'remove count', 0)
2020-05-15 15:08:08,824 - redis_memory.py[line:69] - INFO: ('flush', 'xici:xici_proxy_queue', 'exp', 600, 'remove count', 0)
2020-05-15 15:08:12,830 - redis_memory.py[line:69] - INFO: ('flush', 'xici:xici_proxy_queue', 'exp', 600, 'remove count', 0)
2020-05-15 15:08:16,837 - redis_memory.py[line:69] - INFO: ('flush', 'xici:xici_proxy_queue', 'exp', 600, 'remove count', 0)
2020-05-15 15:08:20,840 - redis_memory.py[line:69] - INFO: ('flush', 'xici:xici_proxy_queue', 'exp', 600, 'remove count', 0)
2020-05-15 15:08:24,843 - redis_memory.py[line:69] - INFO: ('flush', 'xici:xici_proxy_queue', 'exp', 600, 'remove count', 0)
2020-05-15 15:08:28,904 - redis_memory.py[line:69] - INFO: ('flush', 'xici:xici_proxy_queue', 'exp', 600, 'remove count', 0)
2020-05-15 15:08:32,918 - redis_memory.py[line:69] - INFO: ('flush', 'xici:xici_proxy_queue', 'exp', 600, 'remove count', 0)
2020-05-15 15:08:36,921 - redis_memory.py[line:69] - INFO: ('flush', 'xici:xici_proxy_queue', 'exp', 600, 'remove count', 0)
2020-05-15 15:08:40,927 - redis_memory.py[line:69] - INFO: ('flush', 'xici:xici_proxy_queue', 'exp', 600, 'remove count', 0)
2020-05-15 15:08:44,934 - redis_memory.py[line:69] - INFO: ('flush', 'xici:xici_proxy_queue', 'exp', 600, 'remove count', 0)
2020-05-15 15:08:48,939 - redis_memory.py[line:69] - INFO: ('flush', 'xici:xici_proxy_queue', 'exp', 600, 'remove count', 0)
2020-05-15 15:08:52,943 - redis_memory.py[line:69] - INFO: ('flush', 'xici:xici_proxy_queue', 'exp', 600, 'remove count', 0)
2020-05-15 15:08:56,950 - redis_memory.py[line:69] - INFO: ('flush', 'xici:xici_proxy_queue', 'exp', 600, 'remove count', 0)
2020-05-15 15:09:00,979 - redis_memory.py[line:69] - INFO: ('flush', 'xici:xici_proxy_queue', 'exp', 600, 'remove count', 0)
2020-05-15 15:09:04,982 - redis_memory.py[line:69] - INFO: ('flush', 'xici:xici_proxy_queue', 'exp', 600, 'remove count', 0)
2020-05-15 15:09:08,985 - redis_memory.py[line:69] - INFO: ('flush', 'xici:xici_proxy_queue', 'exp', 600, 'remove count', 0)
2020-05-15 15:09:12,991 - redis_memory.py[line:69] - INFO: ('flush', 'xici:xici_proxy_queue', 'exp', 600, 'remove count', 0)
2020-05-15 15:09:16,997 - redis_memory.py[line:69] - INFO: ('flush', 'xici:xici_proxy_queue', 'exp', 600, 'remove count', 0)
2020-05-15 15:09:21,004 - redis_memory.py[line:69] - INFO: ('flush', 'xici:xici_proxy_queue', 'exp', 600, 'remove count', 0)
2020-05-15 15:09:25,009 - redis_memory.py[line:69] - INFO: ('flush', 'xici:xici_proxy_queue', 'exp', 600, 'remove count', 0)
2020-05-15 15:09:29,013 - redis_memory.py[line:69] - INFO: ('flush', 'xici:xici_proxy_queue', 'exp', 600, 'remove count', 0)
2020-05-15 15:09:33,016 - redis_memory.py[line:69] - INFO: ('flush', 'xici:xici_proxy_queue', 'exp', 600, 'remove count', 0)
2020-05-15 15:09:37,022 - redis_memory.py[line:69] - INFO: ('flush', 'xici:xici_proxy_queue', 'exp', 600, 'remove count', 0)
2020-05-15 15:09:41,028 - redis_memory.py[line:69] - INFO: ('flush', 'xici:xici_proxy_queue', 'exp', 600, 'remove count', 0)
2020-05-15 15:09:45,031 - redis_memory.py[line:69] - INFO: ('flush', 'xici:xici_proxy_queue', 'exp', 600, 'remove count', 0)
2020-05-15 15:09:49,035 - redis_memory.py[line:69] - INFO: ('flush', 'xici:xici_proxy_queue', 'exp', 600, 'remove count', 0)
2020-05-15 15:09:53,040 - redis_memory.py[line:69] - INFO: ('flush', 'xici:xici_proxy_queue', 'exp', 600, 'remove count', 0)
2020-05-15 15:09:57,047 - redis_memory.py[line:69] - INFO: ('flush', 'xici:xici_proxy_queue', 'exp', 600, 'remove count', 0)
2020-05-15 15:10:01,052 - redis_memory.py[line:69] - INFO: ('flush', 'xici:xici_proxy_queue', 'exp', 600, 'remove count', 0)
2020-05-15 15:10:05,055 - redis_memory.py[line:69] - INFO: ('flush', 'xici:xici_proxy_queue', 'exp', 600, 'remove count', 0)
2020-05-15 15:10:09,062 - redis_memory.py[line:69] - INFO: ('flush', 'xici:xici_proxy_queue', 'exp', 600, 'remove count', 0)
2020-05-15 15:10:13,066 - redis_memory.py[line:69] - INFO: ('flush', 'xici:xici_proxy_queue', 'exp', 600, 'remove count', 0)
2020-05-15 15:10:17,069 - redis_memory.py[line:69] - INFO: ('flush', 'xici:xici_proxy_queue', 'exp', 600, 'remove count', 0)
2020-05-15 15:10:21,072 - redis_memory.py[line:69] - INFO: ('flush', 'xici:xici_proxy_queue', 'exp', 600, 'remove count', 0)
2020-05-15 15:10:25,078 - redis_memory.py[line:69] - INFO: ('flush', 'xici:xici_proxy_queue', 'exp', 600, 'remove count', 0)
2020-05-15 15:10:29,084 - redis_memory.py[line:69] - INFO: ('flush', 'xici:xici_proxy_queue', 'exp', 600, 'remove count', 0)
2020-05-15 15:10:33,090 - redis_memory.py[line:69] - INFO: ('flush', 'xici:xici_proxy_queue', 'exp', 600, 'remove count', 0)
2020-05-15 15:10:37,096 - redis_memory.py[line:69] - INFO: ('flush', 'xici:xici_proxy_queue', 'exp', 600, 'remove count', 0)
2020-05-15 15:10:41,100 - redis_memory.py[line:69] - INFO: ('flush', 'xici:xici_proxy_queue', 'exp', 600, 'remove count', 0)
2020-05-15 15:10:45,105 - redis_memory.py[line:69] - INFO: ('flush', 'xici:xici_proxy_queue', 'exp', 600, 'remove count', 0)
2020-05-15 15:10:49,109 - redis_memory.py[line:69] - INFO: ('flush', 'xici:xici_proxy_queue', 'exp', 600, 'remove count', 0)
2020-05-15 15:10:53,113 - redis_memory.py[line:69] - INFO: ('flush', 'xici:xici_proxy_queue', 'exp', 600, 'remove count', 0)
2020-05-15 15:10:57,118 - redis_memory.py[line:69] - INFO: ('flush', 'xici:xici_proxy_queue', 'exp', 600, 'remove count', 0)
2020-05-15 15:11:01,124 - redis_memory.py[line:69] - INFO: ('flush', 'xici:xici_proxy_queue', 'exp', 600, 'remove count', 0)
2020-05-15 15:11:05,129 - redis_memory.py[line:69] - INFO: ('flush', 'xici:xici_proxy_queue', 'exp', 600, 'remove count', 0)
2020-05-15 15:11:09,135 - redis_memory.py[line:69] - INFO: ('flush', 'xici:xici_proxy_queue', 'exp', 600, 'remove count', 0)
2020-05-15 15:11:13,139 - redis_memory.py[line:69] - INFO: ('flush', 'xici:xici_proxy_queue', 'exp', 600, 'remove count', 0)
2020-05-15 15:11:17,145 - redis_memory.py[line:69] - INFO: ('flush', 'xici:xici_proxy_queue', 'exp', 600, 'remove count', 0)
2020-05-15 15:11:21,150 - redis_memory.py[line:69] - INFO: ('flush', 'xici:xici_proxy_queue', 'exp', 600, 'remove count', 0)
2020-05-15 15:11:25,154 - redis_memory.py[line:69] - INFO: ('flush', 'xici:xici_proxy_queue', 'exp', 600, 'remove count', 0)
2020-05-15 15:11:29,159 - redis_memory.py[line:69] - INFO: ('flush', 'xici:xici_proxy_queue', 'exp', 600, 'remove count', 0)
2020-05-15 15:11:33,162 - redis_memory.py[line:69] - INFO: ('flush', 'xici:xici_proxy_queue', 'exp', 600, 'remove count', 0)
2020-05-15 15:11:37,168 - redis_memory.py[line:69] - INFO: ('flush', 'xici:xici_proxy_queue', 'exp', 600, 'remove count', 0)
2020-05-15 15:11:41,174 - redis_memory.py[line:69] - INFO: ('flush', 'xici:xici_proxy_queue', 'exp', 600, 'remove count', 0)
2020-05-15 15:11:45,180 - redis_memory.py[line:69] - INFO: ('flush', 'xici:xici_proxy_queue', 'exp', 600, 'remove count', 0)
2020-05-15 15:11:49,187 - redis_memory.py[line:69] - INFO: ('flush', 'xici:xici_proxy_queue', 'exp', 600, 'remove count', 0)
2020-05-15 15:11:53,192 - redis_memory.py[line:69] - INFO: ('flush', 'xici:xici_proxy_queue', 'exp', 600, 'remove count', 0)
2020-05-15 15:11:57,197 - redis_memory.py[line:69] - INFO: ('flush', 'xici:xici_proxy_queue', 'exp', 600, 'remove count', 0)
2020-05-15 15:12:01,201 - redis_memory.py[line:69] - INFO: ('flush', 'xici:xici_proxy_queue', 'exp', 600, 'remove count', 0)
2020-05-15 15:12:05,206 - redis_memory.py[line:69] - INFO: ('flush', 'xici:xici_proxy_queue', 'exp', 600, 'remove count', 0)
2020-05-15 15:12:09,209 - redis_memory.py[line:69] - INFO: ('flush', 'xici:xici_proxy_queue', 'exp', 600, 'remove count', 0)
2020-05-15 15:12:13,213 - redis_memory.py[line:69] - INFO: ('flush', 'xici:xici_proxy_queue', 'exp', 600, 'remove count', 0)
2020-05-15 15:12:17,216 - redis_memory.py[line:69] - INFO: ('flush', 'xici:xici_proxy_queue', 'exp', 600, 'remove count', 0)
2020-05-15 15:12:21,221 - redis_memory.py[line:69] - INFO: ('flush', 'xici:xici_proxy_queue', 'exp', 600, 'remove count', 0)
2020-05-15 15:12:25,226 - redis_memory.py[line:69] - INFO: ('flush', 'xici:xici_proxy_queue', 'exp', 600, 'remove count', 0)
2020-05-15 15:12:29,230 - redis_memory.py[line:69] - INFO: ('flush', 'xici:xici_proxy_queue', 'exp', 600, 'remove count', 0)
2020-05-15 15:12:33,235 - redis_memory.py[line:69] - INFO: ('flush', 'xici:xici_proxy_queue', 'exp', 600, 'remove count', 0)
2020-05-15 15:12:37,240 - redis_memory.py[line:69] - INFO: ('flush', 'xici:xici_proxy_queue', 'exp', 600, 'remove count', 0)
2020-05-15 15:12:41,244 - redis_memory.py[line:69] - INFO: ('flush', 'xici:xici_proxy_queue', 'exp', 600, 'remove count', 0)
2020-05-15 15:12:45,247 - redis_memory.py[line:69] - INFO: ('flush', 'xici:xici_proxy_queue', 'exp', 600, 'remove count', 0)
2020-05-15 15:12:49,250 - redis_memory.py[line:69] - INFO: ('flush', 'xici:xici_proxy_queue', 'exp', 600, 'remove count', 0)
